Workbook

Sheet SAIDI excl MEDs sort (5-yr avg)
A1: Quartile | B1: FEEDERID | C1: Substation Name | D1: Circuit Name | E1: City | F1: 5-Year Avg Cust Count | G1: 2023 | K1: 2022 | O1: 2021 | S1: 2020 | W1: 2019
G2: All Weather | I2: Excluding MEDs | K2: All Weather | M2: Excluding MEDs | O2: All Weather | Q2: Excluding MEDs | S2: All Weather | U2: Excluding MEDs | W2: All Weather | Y2: Excluding MEDs
G3: SAIDI | H3: SAIFI | I3: SAIDI | J3: SAIFI | K3: SAIDI | L3: SAIFI | M3: SAIDI | N3: SAIFI | O3: SAIDI | P3: SAIFI | Q3: SAIDI | R3: SAIFI | S3: SAIDI | T3: SAIFI | U3: SAIDI | V3: SAIFI | W3: SAIDI | X3: SAIFI | Y3: SAIDI | Z3: SAIFI | AA3: 5-year average SAIDI excl MEDs
A4: Fourth Quartile | B4: 090102 | C4: WAGER | D4: PARKLAND | E4: Flint | F4: =IFERROR(INDEX([1]raw_data!B:B,MATCH('SAIDI excl MEDs sort (5-yr avg)'!B105,[1]raw_data!A:A,0)),0) -> 1734.2 | G4: =SUMIFS([1]raw_data!C:C,[1]raw_data!$A:$A,$B4) -> 36.783123 | H4: =SUMIFS([1]raw_data!D:D,[1]raw_data!$A:$A,$B4) -> 0.18711386 | I4: =SUMIFS([1]raw_data!E:E,[1]raw_data!$A:$A,$B4) -> 36.783123 | J4: =SUMIFS([1]raw_data!F:F,[1]raw_data!$A:$A,$B4) -> 0.18711386 | K4: =SUMIFS([1]raw_data!G:G,[1]raw_data!$A:$A,$B4) -> 355.56214 | L4: =SUMIFS([1]raw_data!H:H,[1]raw_data!$A:$A,$B4) -> 1.1356958 | M4: =SUMIFS([1]raw_data!I:I,[1]raw_data!$A:$A,$B4) -> 338.43867 | N4: =SUMIFS([1]raw_data!J:J,[1]raw_data!$A:$A,$B4) -> 1.127917 | O4: =SUMIFS([1]raw_data!K:K,[1]raw_data!$A:$A,$B4) -> 283.72984 | P4: =SUMIFS([1]raw_data!L:L,[1]raw_data!$A:$A,$B4) -> 0.18836565 | Q4: =SUMIFS([1]raw_data!M:M,[1]raw_data!$A:$A,$B4) -> 34.433995 | R4: =SUMIFS([1]raw_data!N:N,[1]raw_data!$A:$A,$B4) -> 0.093259464 | S4: =SUMIFS([1]raw_data!O:O,[1]raw_data!$A:$A,$B4) -> 88.714451 | T4: =SUMIFS([1]raw_data!P:P,[1]raw_data!$A:$A,$B4) -> 0.21058559 | U4: =SUMIFS([1]raw_data!Q:Q,[1]raw_data!$A:$A,$B4) -> 70.178622 | V4: =SUMIFS([1]raw_data!R:R,[1]raw_data!$A:$A,$B4) -> 0.2027027 | W4: =SUMIFS([1]raw_data!S:S,[1]raw_data!$A:$A,$B4) -> 2912.5 | X4: =SUMIFS([1]raw_data!T:T,[1]raw_data!$A:$A,$B4) -> 10 | Y4: =SUMIFS([1]raw_data!U:U,[1]raw_data!$A:$A,$B4) -> 2912.5 | Z4: =SUMIFS([1]raw_data!V:V,[1]raw_data!$A:$A,$B4) -> 10 | AA4: =(I4+M4+Q4+U4+Y4)/5 -> 678.46688
B5: 010002 | C5: WEALTHY STREET | D5: BUTTERWORTH | E5: Grand Rapids | F5: =IFERROR(INDEX([1]raw_data!B:B,MATCH('SAIDI excl MEDs sort (5-yr avg)'!B152,[1]raw_data!A:A,0)),0) -> 1850.6 | G5: =SUMIFS([1]raw_data!C:C,[1]raw_data!$A:$A,$B5) -> 2.092328 | H5: =SUMIFS([1]raw_data!D:D,[1]raw_data!$A:$A,$B5) -> 0.027027027 | I5: =SUMIFS([1]raw_data!E:E,[1]raw_data!$A:$A,$B5) -> 2.092328 | J5: =SUMIFS([1]raw_data!F:F,[1]raw_data!$A:$A,$B5) -> 0.027027027 | K5: =SUMIFS([1]raw_data!G:G,[1]raw_data!$A:$A,$B5) -> 10.627009 | L5: =SUMIFS([1]raw_data!H:H,[1]raw_data!$A:$A,$B5) -> 0.091743119 | M5: =SUMIFS([1]raw_data!I:I,[1]raw_data!$A:$A,$B5) -> 10.627009 | N5: =SUMIFS([1]raw_data!J:J,[1]raw_data!$A:$A,$B5) -> 0.091743119 | O5: =SUMIFS([1]raw_data!K:K,[1]raw_data!$A:$A,$B5) -> 33.639042 | P5: =SUMIFS([1]raw_data!L:L,[1]raw_data!$A:$A,$B5) -> 0.10185185 | Q5: =SUMIFS([1]raw_data!M:M,[1]raw_data!$A:$A,$B5) -> 5.694444 | R5: =SUMIFS([1]raw_data!N:N,[1]raw_data!$A:$A,$B5) -> 0.092592593 | S5: =SUMIFS([1]raw_data!O:O,[1]raw_data!$A:$A,$B5) -> 143.33302 | T5: =SUMIFS([1]raw_data!P:P,[1]raw_data!$A:$A,$B5) -> 1.0283019 | U5: =SUMIFS([1]raw_data!Q:Q,[1]raw_data!$A:$A,$B5) -> 143.33302 | V5: =SUMIFS([1]raw_data!R:R,[1]raw_data!$A:$A,$B5) -> 1.0283019 | W5: =SUMIFS([1]raw_data!S:S,[1]raw_data!$A:$A,$B5) -> 2794.5473 | X5: =SUMIFS([1]raw_data!T:T,[1]raw_data!$A:$A,$B5) -> 20.55814 | Y5: =SUMIFS([1]raw_data!U:U,[1]raw_data!$A:$A,$B5) -> 2794.5473 | Z5: =SUMIFS([1]raw_data!V:V,[1]raw_data!$A:$A,$B5) -> 20.55814 | AA5: =(I5+M5+Q5+U5+Y5)/5 -> 591.25882
B6: 060801 | C6: PALMER | D6: REED | E6: Kalamazoo | F6: =IFERROR(INDEX([1]raw_data!B:B,MATCH('SAIDI excl MEDs sort (5-yr avg)'!B8,[1]raw_data!A:A,0)),0) -> 896 | G6: =SUMIFS([1]raw_data!C:C,[1]raw_data!$A:$A,$B6) -> 679.65556 | H6: =SUMIFS([1]raw_data!D:D,[1]raw_data!$A:$A,$B6) -> 2.1329114 | I6: =SUMIFS([1]raw_data!E:E,[1]raw_data!$A:$A,$B6) -> 557.56306 | J6: =SUMIFS([1]raw_data!F:F,[1]raw_data!$A:$A,$B6) -> 2.1012658 | K6: =SUMIFS([1]raw_data!G:G,[1]raw_data!$A:$A,$B6) -> 2129.2801 | L6: =SUMIFS([1]raw_data!H:H,[1]raw_data!$A:$A,$B6) -> 4.45 | M6: =SUMIFS([1]raw_data!I:I,[1]raw_data!$A:$A,$B6) -> 694.74956 | N6: =SUMIFS([1]raw_data!J:J,[1]raw_data!$A:$A,$B6) -> 2.31875 | O6: =SUMIFS([1]raw_data!K:K,[1]raw_data!$A:$A,$B6) -> 2045.774 | P6: =SUMIFS([1]raw_data!L:L,[1]raw_data!$A:$A,$B6) -> 2.7445483 | Q6: =SUMIFS([1]raw_data!M:M,[1]raw_data!$A:$A,$B6) -> 425.37077 | R6: =SUMIFS([1]raw_data!N:N,[1]raw_data!$A:$A,$B6) -> 1.0965732 | S6: =SUMIFS([1]raw_data!O:O,[1]raw_data!$A:$A,$B6) -> 8.754114 | T6: =SUMIFS([1]raw_data!P:P,[1]raw_data!$A:$A,$B6) -> 0.10185185 | U6: =SUMIFS([1]raw_data!Q:Q,[1]raw_data!$A:$A,$B6) -> 2.545061 | V6: =SUMIFS([1]raw_data!R:R,[1]raw_data!$A:$A,$B6) -> 0.052469136 | W6: =SUMIFS([1]raw_data!S:S,[1]raw_data!$A:$A,$B6) -> 864.60437 | X6: =SUMIFS([1]raw_data!T:T,[1]raw_data!$A:$A,$B6) -> 3.55625 | Y6: =SUMIFS([1]raw_data!U:U,[1]raw_data!$A:$A,$B6) -> 861.11427 | Z6: =SUMIFS([1]raw_data!V:V,[1]raw_data!$A:$A,$B6) -> 3.49375 | AA6: =(I6+M6+Q6+U6+Y6)/5 -> 508.26854
B7: 077602 | C7: KEATING | D7: LAKETON | E7: Muskegon | F7: =IFERROR(INDEX([1]raw_data!B:B,MATCH('SAIDI excl MEDs sort (5-yr avg)'!B31,[1]raw_data!A:A,0)),0) -> 1071.2222 | G7: =SUMIFS([1]raw_data!C:C,[1]raw_data!$A:$A,$B7) -> 960.6522 | H7: =SUMIFS([1]raw_data!D:D,[1]raw_data!$A:$A,$B7) -> 3.2951886 | I7: =SUMIFS([1]raw_data!E:E,[1]raw_data!$A:$A,$B7) -> 220.01797 | J7: =SUMIFS([1]raw_data!F:F,[1]raw_data!$A:$A,$B7) -> 2.3784135 | K7: =SUMIFS([1]raw_data!G:G,[1]raw_data!$A:$A,$B7) -> 11.529491 | L7: =SUMIFS([1]raw_data!H:H,[1]raw_data!$A:$A,$B7) -> 0.16103896 | M7: =SUMIFS([1]raw_data!I:I,[1]raw_data!$A:$A,$B7) -> 11.529491 | N7: =SUMIFS([1]raw_data!J:J,[1]raw_data!$A:$A,$B7) -> 0.16103896 | O7: =SUMIFS([1]raw_data!K:K,[1]raw_data!$A:$A,$B7) -> 543.74913 | P7: =SUMIFS([1]raw_data!L:L,[1]raw_data!$A:$A,$B7) -> 3.2786458 | Q7: =SUMIFS([1]raw_data!M:M,[1]raw_data!$A:$A,$B7) -> 462.26322 | R7: =SUMIFS([1]raw_data!N:N,[1]raw_data!$A:$A,$B7) -> 3.1966146 | S7: =SUMIFS([1]raw_data!O:O,[1]raw_data!$A:$A,$B7) -> 1222.8187 | T7: =SUMIFS([1]raw_data!P:P,[1]raw_data!$A:$A,$B7) -> 6.4159061 | U7: =SUMIFS([1]raw_data!Q:Q,[1]raw_data!$A:$A,$B7) -> 1024.0025 | V7: =SUMIFS([1]raw_data!R:R,[1]raw_data!$A:$A,$B7) -> 5.9530639 | W7: =SUMIFS([1]raw_data!S:S,[1]raw_data!$A:$A,$B7) -> 2392.2078 | X7: =SUMIFS([1]raw_data!T:T,[1]raw_data!$A:$A,$B7) -> 5.7562582 | Y7: =SUMIFS([1]raw_data!U:U,[1]raw_data!$A:$A,$B7) -> 746.78474 | Z7: =SUMIFS([1]raw_data!V:V,[1]raw_data!$A:$A,$B7) -> 4.6455863 | AA7: =(I7+M7+Q7+U7+Y7)/5 -> 492.91959
B8: 006402 | C8: BEECHER | D8: TOLEDO ROAD | E8: Adrian | F8: =IFERROR(INDEX([1]raw_data!B:B,MATCH('SAIDI excl MEDs sort (5-yr avg)'!B5,[1]raw_data!A:A,0)),0) -> 97.5 | G8: =SUMIFS([1]raw_data!C:C,[1]raw_data!$A:$A,$B8) -> 1584.2807 | H8: =SUMIFS([1]raw_data!D:D,[1]raw_data!$A:$A,$B8) -> 8.6051587 | I8: =SUMIFS([1]raw_data!E:E,[1]raw_data!$A:$A,$B8) -> 963.49289 | J8: =SUMIFS([1]raw_data!F:F,[1]raw_data!$A:$A,$B8) -> 5.9980159 | K8: =SUMIFS([1]raw_data!G:G,[1]raw_data!$A:$A,$B8) -> 138.46224 | L8: =SUMIFS([1]raw_data!H:H,[1]raw_data!$A:$A,$B8) -> 1.5803842 | M8: =SUMIFS([1]raw_data!I:I,[1]raw_data!$A:$A,$B8) -> 137.17637 | N8: =SUMIFS([1]raw_data!J:J,[1]raw_data!$A:$A,$B8) -> 1.5733064 | O8: =SUMIFS([1]raw_data!K:K,[1]raw_data!$A:$A,$B8) -> 18.361093 | P8: =SUMIFS([1]raw_data!L:L,[1]raw_data!$A:$A,$B8) -> 0.23175542 | Q8: =SUMIFS([1]raw_data!M:M,[1]raw_data!$A:$A,$B8) -> 18.212836 | R8: =SUMIFS([1]raw_data!N:N,[1]raw_data!$A:$A,$B8) -> 0.22978304 | S8: =SUMIFS([1]raw_data!O:O,[1]raw_data!$A:$A,$B8) -> 124.69533 | T8: =SUMIFS([1]raw_data!P:P,[1]raw_data!$A:$A,$B8) -> 1.0238501 | U8: =SUMIFS([1]raw_data!Q:Q,[1]raw_data!$A:$A,$B8) -> 124.69533 | V8: =SUMIFS([1]raw_data!R:R,[1]raw_data!$A:$A,$B8) -> 1.0238501 | W8: =SUMIFS([1]raw_data!S:S,[1]raw_data!$A:$A,$B8) -> 831.64991 | X8: =SUMIFS([1]raw_data!T:T,[1]raw_data!$A:$A,$B8) -> 3.0857143 | Y8: =SUMIFS([1]raw_data!U:U,[1]raw_data!$A:$A,$B8) -> 831.64991 | Z8: =SUMIFS([1]raw_data!V:V,[1]raw_data!$A:$A,$B8) -> 3.0857143 | AA8: =(I8+M8+Q8+U8+Y8)/5 -> 415.04547
B9: 060802 | C9: PALMER | D9: HEALY | E9: Kalamazoo | F9: =IFERROR(INDEX([1]raw_data!B:B,MATCH('SAIDI excl MEDs sort (5-yr avg)'!B38,[1]raw_data!A:A,0)),0) -> 1789.8 | G9: =SUMIFS([1]raw_data!C:C,[1]raw_data!$A:$A,$B9) -> 972.31506 | H9: =SUMIFS([1]raw_data!D:D,[1]raw_data!$A:$A,$B9) -> 1.7241379 | I9: =SUMIFS([1]raw_data!E:E,[1]raw_data!$A:$A,$B9) -> 182.19842 | J9: =SUMIFS([1]raw_data!F:F,[1]raw_data!$A:$A,$B9) -> 1.4094828 | K9: =SUMIFS([1]raw_data!G:G,[1]raw_data!$A:$A,$B9) -> 848.48059 | L9: =SUMIFS([1]raw_data!H:H,[1]raw_data!$A:$A,$B9) -> 2 | M9: =SUMIFS([1]raw_data!I:I,[1]raw_data!$A:$A,$B9) -> 848.48059 | N9: =SUMIFS([1]raw_data!J:J,[1]raw_data!$A:$A,$B9) -> 2 | O9: =SUMIFS([1]raw_data!K:K,[1]raw_data!$A:$A,$B9) -> 14.829824 | P9: =SUMIFS([1]raw_data!L:L,[1]raw_data!$A:$A,$B9) -> 0.030701754 | Q9: =SUMIFS([1]raw_data!M:M,[1]raw_data!$A:$A,$B9) -> 11.219444 | R9: =SUMIFS([1]raw_data!N:N,[1]raw_data!$A:$A,$B9) -> 0.021929825 | S9: =SUMIFS([1]raw_data!O:O,[1]raw_data!$A:$A,$B9) -> 542.36747 | T9: =SUMIFS([1]raw_data!P:P,[1]raw_data!$A:$A,$B9) -> 4.0396476 | U9: =SUMIFS([1]raw_data!Q:Q,[1]raw_data!$A:$A,$B9) -> 542.36747 | V9: =SUMIFS([1]raw_data!R:R,[1]raw_data!$A:$A,$B9) -> 4.0396476 | W9: =SUMIFS([1]raw_data!S:S,[1]raw_data!$A:$A,$B9) -> 431.47485 | X9: =SUMIFS([1]raw_data!T:T,[1]raw_data!$A:$A,$B9) -> 1.2982456 | Y9: =SUMIFS([1]raw_data!U:U,[1]raw_data!$A:$A,$B9) -> 430.52741 | Z9: =SUMIFS([1]raw_data!V:V,[1]raw_data!$A:$A,$B9) -> 1.2938596 | AA9: =(I9+M9+Q9+U9+Y9)/5 -> 402.95867
B10: 058604 | C10: LEITH STREET | D10: WESTERN ROAD | E10: Flint | F10: =IFERROR(INDEX([1]raw_data!B:B,MATCH('SAIDI excl MEDs sort (5-yr avg)'!B17,[1]raw_data!A:A,0)),0) -> 281.375 | G10: =SUMIFS([1]raw_data!C:C,[1]raw_data!$A:$A,$B10) -> 324.26567 | H10: =SUMIFS([1]raw_data!D:D,[1]raw_data!$A:$A,$B10) -> 1.9806397 | I10: =SUMIFS([1]raw_data!E:E,[1]raw_data!$A:$A,$B10) -> 303.22485 | J10: =SUMIFS([1]raw_data!F:F,[1]raw_data!$A:$A,$B10) -> 1.9638047 | K10: =SUMIFS([1]raw_data!G:G,[1]raw_data!$A:$A,$B10) -> 779.8456 | L10: =SUMIFS([1]raw_data!H:H,[1]raw_data!$A:$A,$B10) -> 2.6413043 | M10: =SUMIFS([1]raw_data!I:I,[1]raw_data!$A:$A,$B10) -> 610.75228 | N10: =SUMIFS([1]raw_data!J:J,[1]raw_data!$A:$A,$B10) -> 2.5351171 | O10: =SUMIFS([1]raw_data!K:K,[1]raw_data!$A:$A,$B10) -> 701.83879 | P10: =SUMIFS([1]raw_data!L:L,[1]raw_data!$A:$A,$B10) -> 3.9368155 | Q10: =SUMIFS([1]raw_data!M:M,[1]raw_data!$A:$A,$B10) -> 688.37534 | R10: =SUMIFS([1]raw_data!N:N,[1]raw_data!$A:$A,$B10) -> 3.9098568 | S10: =SUMIFS([1]raw_data!O:O,[1]raw_data!$A:$A,$B10) -> 249.56802 | T10: =SUMIFS([1]raw_data!P:P,[1]raw_data!$A:$A,$B10) -> 0.50040096 | U10: =SUMIFS([1]raw_data!Q:Q,[1]raw_data!$A:$A,$B10) -> 87.75989 | V10: =SUMIFS([1]raw_data!R:R,[1]raw_data!$A:$A,$B10) -> 0.37610265 | W10: =SUMIFS([1]raw_data!S:S,[1]raw_data!$A:$A,$B10) -> 684.83887 | X10: =SUMIFS([1]raw_data!T:T,[1]raw_data!$A:$A,$B10) -> 1.2433947 | Y10: =SUMIFS([1]raw_data!U:U,[1]raw_data!$A:$A,$B10) -> 282.07016 | Z10: =SUMIFS([1]raw_data!V:V,[1]raw_data!$A:$A,$B10) -> 1.0536429 | AA10: =(I10+M10+Q10+U10+Y10)/5 -> 394.43651 | AC10: SAIDI incl MEDs quartiles | AD10: Column1 | AE10: Column2 | AF10: Column3
B11: 060804 | C11: PALMER | D11: WATER LIFT | E11: Kalamazoo | F11: =IFERROR(INDEX([1]raw_data!B:B,MATCH('SAIDI excl MEDs sort (5-yr avg)'!B81,[1]raw_data!A:A,0)),0) -> 739.11111 | G11: =SUMIFS([1]raw_data!C:C,[1]raw_data!$A:$A,$B11) -> 82.039223 | H11: =SUMIFS([1]raw_data!D:D,[1]raw_data!$A:$A,$B11) -> 0.1759379 | I11: =SUMIFS([1]raw_data!E:E,[1]raw_data!$A:$A,$B11) -> 66.8473 | J11: =SUMIFS([1]raw_data!F:F,[1]raw_data!$A:$A,$B11) -> 0.16817594 | K11: =SUMIFS([1]raw_data!G:G,[1]raw_data!$A:$A,$B11) -> 30.98042 | L11: =SUMIFS([1]raw_data!H:H,[1]raw_data!$A:$A,$B11) -> 0.18158568 | M11: =SUMIFS([1]raw_data!I:I,[1]raw_data!$A:$A,$B11) -> 16.733418 | N11: =SUMIFS([1]raw_data!J:J,[1]raw_data!$A:$A,$B11) -> 0.12531969 | O11: =SUMIFS([1]raw_data!K:K,[1]raw_data!$A:$A,$B11) -> 275.75771 | P11: =SUMIFS([1]raw_data!L:L,[1]raw_data!$A:$A,$B11) -> 1.3910256 | Q11: =SUMIFS([1]raw_data!M:M,[1]raw_data!$A:$A,$B11) -> 245.56743 | R11: =SUMIFS([1]raw_data!N:N,[1]raw_data!$A:$A,$B11) -> 1.3474359 | S11: =SUMIFS([1]raw_data!O:O,[1]raw_data!$A:$A,$B11) -> 206.52351 | T11: =SUMIFS([1]raw_data!P:P,[1]raw_data!$A:$A,$B11) -> 2.0663265 | U11: =SUMIFS([1]raw_data!Q:Q,[1]raw_data!$A:$A,$B11) -> 188.18597 | V11: =SUMIFS([1]raw_data!R:R,[1]raw_data!$A:$A,$B11) -> 1.997449 | W11: =SUMIFS([1]raw_data!S:S,[1]raw_data!$A:$A,$B11) -> 1422.1092 | X11: =SUMIFS([1]raw_data!T:T,[1]raw_data!$A:$A,$B11) -> 4.3009368 | Y11: =SUMIFS([1]raw_data!U:U,[1]raw_data!$A:$A,$B11) -> 1422.1092 | Z11: =SUMIFS([1]raw_data!V:V,[1]raw_data!$A:$A,$B11) -> 4.3009368 | AA11: =(I11+M11+Q11+U11+Y11)/5 -> 387.88867 | AC11: Quartile | AD11: SAIDI | AE11: # of Circuits | AF11: # of customers
B12: 061805 | C12: LAGRAVE | D12: MAPLE | E12: Grand Rapids | F12: =IFERROR(INDEX([1]raw_data!B:B,MATCH('SAIDI excl MEDs sort (5-yr avg)'!B155,[1]raw_data!A:A,0)),0) -> 170 | G12: =SUMIFS([1]raw_data!C:C,[1]raw_data!$A:$A,$B12) -> 1.494802 | H12: =SUMIFS([1]raw_data!D:D,[1]raw_data!$A:$A,$B12) -> 0.0096153846 | I12: =SUMIFS([1]raw_data!E:E,[1]raw_data!$A:$A,$B12) -> 1.494802 | J12: =SUMIFS([1]raw_data!F:F,[1]raw_data!$A:$A,$B12) -> 0.0096153846 | K12: =SUMIFS([1]raw_data!G:G,[1]raw_data!$A:$A,$B12) -> 729.53538 | L12: =SUMIFS([1]raw_data!H:H,[1]raw_data!$A:$A,$B12) -> 0.99056604 | M12: =SUMIFS([1]raw_data!I:I,[1]raw_data!$A:$A,$B12) -> 729.53538 | N12: =SUMIFS([1]raw_data!J:J,[1]raw_data!$A:$A,$B12) -> 0.99056604 | O12: =SUMIFS([1]raw_data!K:K,[1]raw_data!$A:$A,$B12) -> 7.54299 | P12: =SUMIFS([1]raw_data!L:L,[1]raw_data!$A:$A,$B12) -> 0.056074766 | Q12: =SUMIFS([1]raw_data!M:M,[1]raw_data!$A:$A,$B12) -> 7.54299 | R12: =SUMIFS([1]raw_data!N:N,[1]raw_data!$A:$A,$B12) -> 0.056074766 | S12: =SUMIFS([1]raw_data!O:O,[1]raw_data!$A:$A,$B12) -> 32.553703 | T12: =SUMIFS([1]raw_data!P:P,[1]raw_data!$A:$A,$B12) -> 0.73015873 | U12: =SUMIFS([1]raw_data!Q:Q,[1]raw_data!$A:$A,$B12) -> 32.553703 | V12: =SUMIFS([1]raw_data!R:R,[1]raw_data!$A:$A,$B12) -> 0.73015873 | W12: =SUMIFS([1]raw_data!S:S,[1]raw_data!$A:$A,$B12) -> 1089.061 | X12: =SUMIFS([1]raw_data!T:T,[1]raw_data!$A:$A,$B12) -> 2.9849624 | Y12: =SUMIFS([1]raw_data!U:U,[1]raw_data!$A:$A,$B12) -> 1089.061 | Z12: =SUMIFS([1]raw_data!V:V,[1]raw_data!$A:$A,$B12) -> 2.9849624 | AA12: =(I12+M12+Q12+U12+Y12)/5 -> 372.03758 | AC12: Q1 SAIDI | AD12: <90 | AE12: =COUNT(AA114:AA193) -> 80 | AF12: =SUM(F114:F193) -> 62676.566 | AH12: 11 ckts in Q1 were in other quartiles for 2023 only
B13: 090103 | C13: WAGER | D13: MARENGO | E13: Flint | F13: =IFERROR(INDEX([1]raw_data!B:B,MATCH('SAIDI excl MEDs sort (5-yr avg)'!B128,[1]raw_data!A:A,0)),0) -> 145.42857 | G13: =SUMIFS([1]raw_data!C:C,[1]raw_data!$A:$A,$B13) -> 4.924718 | H13: =SUMIFS([1]raw_data!D:D,[1]raw_data!$A:$A,$B13) -> 0.043010753 | I13: =SUMIFS([1]raw_data!E:E,[1]raw_data!$A:$A,$B13) -> 4.924718 | J13: =SUMIFS([1]raw_data!F:F,[1]raw_data!$A:$A,$B13) -> 0.043010753 | K13: =SUMIFS([1]raw_data!G:G,[1]raw_data!$A:$A,$B13) -> 804.01911 | L13: =SUMIFS([1]raw_data!H:H,[1]raw_data!$A:$A,$B13) -> 2.8947368 | M13: =SUMIFS([1]raw_data!I:I,[1]raw_data!$A:$A,$B13) -> 494.93491 | N13: =SUMIFS([1]raw_data!J:J,[1]raw_data!$A:$A,$B13) -> 1.0315789 | O13: =SUMIFS([1]raw_data!K:K,[1]raw_data!$A:$A,$B13) -> 3065.1187 | P13: =SUMIFS([1]raw_data!L:L,[1]raw_data!$A:$A,$B13) -> 2.078125 | Q13: =SUMIFS([1]raw_data!M:M,[1]raw_data!$A:$A,$B13) -> 304.7921 | R13: =SUMIFS([1]raw_data!N:N,[1]raw_data!$A:$A,$B13) -> 1.0625 | S13: =SUMIFS([1]raw_data!O:O,[1]raw_data!$A:$A,$B13) -> 862.62482 | T13: =SUMIFS([1]raw_data!P:P,[1]raw_data!$A:$A,$B13) -> 2.6861702 | U13: =SUMIFS([1]raw_data!Q:Q,[1]raw_data!$A:$A,$B13) -> 814.02589 | V13: =SUMIFS([1]raw_data!R:R,[1]raw_data!$A:$A,$B13) -> 2.6702128 | W13: =SUMIFS([1]raw_data!S:S,[1]raw_data!$A:$A,$B13) -> 398.0961 | X13: =SUMIFS([1]raw_data!T:T,[1]raw_data!$A:$A,$B13) -> 1.2978723 | Y13: =SUMIFS([1]raw_data!U:U,[1]raw_data!$A:$A,$B13) -> 223.07057 | Z13: =SUMIFS([1]raw_data!V:V,[1]raw_data!$A:$A,$B13) -> 1.2553191 | AA13: =(I13+M13+Q13+U13+Y13)/5 -> 368.34964 | AC13: Q2 SAIDI | AD13: 90-131 | AE13: =COUNT(AA76:AA113) -> 38 | AF13: =SUM(F76:F113) -> 41688.738 | AH13: 36 ckts in Q2 were in other quartiles for 2023 only
B14: 072602 | C14: MAYNARD | D14: BESTWALL | E14: Grand Rapids | F14: =IFERROR(INDEX([1]raw_data!B:B,MATCH('SAIDI excl MEDs sort (5-yr avg)'!B113,[1]raw_data!A:A,0)),0) -> 3001.7778 | G14: =SUMIFS([1]raw_data!C:C,[1]raw_data!$A:$A,$B14) -> 28.890062 | H14: =SUMIFS([1]raw_data!D:D,[1]raw_data!$A:$A,$B14) -> 0.12903226 | I14: =SUMIFS([1]raw_data!E:E,[1]raw_data!$A:$A,$B14) -> 28.890062 | J14: =SUMIFS([1]raw_data!F:F,[1]raw_data!$A:$A,$B14) -> 0.12903226 | K14: =SUMIFS([1]raw_data!G:G,[1]raw_data!$A:$A,$B14) -> 169.45606 | L14: =SUMIFS([1]raw_data!H:H,[1]raw_data!$A:$A,$B14) -> 1.0967742 | M14: =SUMIFS([1]raw_data!I:I,[1]raw_data!$A:$A,$B14) -> 169.45606 | N14: =SUMIFS([1]raw_data!J:J,[1]raw_data!$A:$A,$B14) -> 1.0967742 | O14: =SUMIFS([1]raw_data!K:K,[1]raw_data!$A:$A,$B14) -> 774.29624 | P14: =SUMIFS([1]raw_data!L:L,[1]raw_data!$A:$A,$B14) -> 0.38709677 | Q14: =SUMIFS([1]raw_data!M:M,[1]raw_data!$A:$A,$B14) -> 226.41882 | R14: =SUMIFS([1]raw_data!N:N,[1]raw_data!$A:$A,$B14) -> 0.25806452 | S14: =SUMIFS([1]raw_data!O:O,[1]raw_data!$A:$A,$B14) -> 95.686666 | T14: =SUMIFS([1]raw_data!P:P,[1]raw_data!$A:$A,$B14) -> 1.1 | U14: =SUMIFS([1]raw_data!Q:Q,[1]raw_data!$A:$A,$B14) -> 95.686666 | V14: =SUMIFS([1]raw_data!R:R,[1]raw_data!$A:$A,$B14) -> 1.1 | W14: =SUMIFS([1]raw_data!S:S,[1]raw_data!$A:$A,$B14) -> 3096.9844 | X14: =SUMIFS([1]raw_data!T:T,[1]raw_data!$A:$A,$B14) -> 4.625 | Y14: =SUMIFS([1]raw_data!U:U,[1]raw_data!$A:$A,$B14) -> 1302.8073 | Z14: =SUMIFS([1]raw_data!V:V,[1]raw_data!$A:$A,$B14) -> 3.5625 | AA14: =(I14+M14+Q14+U14+Y14)/5 -> 364.65178 | AC14: Q3 SAIDI | AD14: 131-191 | AE14: =COUNT(AA41:AA75) -> 35 | AF14: =SUM(F41:F75) -> 32578.753 | AH14: 27 ckts in Q3 were in other quartiles for 2023 only
B15: 036001 | C15: LIBERTY | D15: WASHINGTON | E15: Battle Creek | F15: =IFERROR(INDEX([1]raw_data!B:B,MATCH('SAIDI excl MEDs sort (5-yr avg)'!B52,[1]raw_data!A:A,0)),0) -> 3867.4 | G15: =SUMIFS([1]raw_data!C:C,[1]raw_data!$A:$A,$B15) -> 319.7433 | H15: =SUMIFS([1]raw_data!D:D,[1]raw_data!$A:$A,$B15) -> 1.4084302 | I15: =SUMIFS([1]raw_data!E:E,[1]raw_data!$A:$A,$B15) -> 137.58238 | J15: =SUMIFS([1]raw_data!F:F,[1]raw_data!$A:$A,$B15) -> 0.9752907 | K15: =SUMIFS([1]raw_data!G:G,[1]raw_data!$A:$A,$B15) -> 212.18552 | L15: =SUMIFS([1]raw_data!H:H,[1]raw_data!$A:$A,$B15) -> 1.8479197 | M15: =SUMIFS([1]raw_data!I:I,[1]raw_data!$A:$A,$B15) -> 160.96566 | N15: =SUMIFS([1]raw_data!J:J,[1]raw_data!$A:$A,$B15) -> 1.8278336 | O15: =SUMIFS([1]raw_data!K:K,[1]raw_data!$A:$A,$B15) -> 1162.8149 | P15: =SUMIFS([1]raw_data!L:L,[1]raw_data!$A:$A,$B15) -> 1.9281609 | Q15: =SUMIFS([1]raw_data!M:M,[1]raw_data!$A:$A,$B15) -> 334.13676 | R15: =SUMIFS([1]raw_data!N:N,[1]raw_data!$A:$A,$B15) -> 0.97844828 | S15: =SUMIFS([1]raw_data!O:O,[1]raw_data!$A:$A,$B15) -> 2639.6718 | T15: =SUMIFS([1]raw_data!P:P,[1]raw_data!$A:$A,$B15) -> 5.5354059 | U15: =SUMIFS([1]raw_data!Q:Q,[1]raw_data!$A:$A,$B15) -> 457.83952 | V15: =SUMIFS([1]raw_data!R:R,[1]raw_data!$A:$A,$B15) -> 4.3402418 | W15: =SUMIFS([1]raw_data!S:S,[1]raw_data!$A:$A,$B15) -> 1204.6405 | X15: =SUMIFS([1]raw_data!T:T,[1]raw_data!$A:$A,$B15) -> 4.4731369 | Y15: =SUMIFS([1]raw_data!U:U,[1]raw_data!$A:$A,$B15) -> 624.11606 | Z15: =SUMIFS([1]raw_data!V:V,[1]raw_data!$A:$A,$B15) -> 2.94974 | AA15: =(I15+M15+Q15+U15+Y15)/5 -> 342.92808 | AC15: Q4 SAIDI | AD15: >191 | AE15: =COUNT(AA4:AA40) -> 37 | AF15: =SUM(F4:F40) -> 37432.257 | AH15: 26 ckts in Q4 were in other quartiles for 2023 only
B16: 106601 | C16: ALDRICH | D16: TRAVERSE | E16: Flint | F16: =IFERROR(INDEX([1]raw_data!B:B,MATCH('SAIDI excl MEDs sort (5-yr avg)'!B51,[1]raw_data!A:A,0)),0) -> 490.6 | G16: =SUMIFS([1]raw_data!C:C,[1]raw_data!$A:$A,$B16) -> 96.34051 | H16: =SUMIFS([1]raw_data!D:D,[1]raw_data!$A:$A,$B16) -> 0.54225352 | I16: =SUMIFS([1]raw_data!E:E,[1]raw_data!$A:$A,$B16) -> 64.690905 | J16: =SUMIFS([1]raw_data!F:F,[1]raw_data!$A:$A,$B16) -> 0.45070423 | K16: =SUMIFS([1]raw_data!G:G,[1]raw_data!$A:$A,$B16) -> 115.37966 | L16: =SUMIFS([1]raw_data!H:H,[1]raw_data!$A:$A,$B16) -> 0.77277277 | M16: =SUMIFS([1]raw_data!I:I,[1]raw_data!$A:$A,$B16) -> 86.368158 | N16: =SUMIFS([1]raw_data!J:J,[1]raw_data!$A:$A,$B16) -> 0.75175175 | O16: =SUMIFS([1]raw_data!K:K,[1]raw_data!$A:$A,$B16) -> 510.86051 | P16: =SUMIFS([1]raw_data!L:L,[1]raw_data!$A:$A,$B16) -> 3.0797546 | Q16: =SUMIFS([1]raw_data!M:M,[1]raw_data!$A:$A,$B16) -> 476.02249 | R16: =SUMIFS([1]raw_data!N:N,[1]raw_data!$A:$A,$B16) -> 3.0501022 | S16: =SUMIFS([1]raw_data!O:O,[1]raw_data!$A:$A,$B16) -> 347.23569 | T16: =SUMIFS([1]raw_data!P:P,[1]raw_data!$A:$A,$B16) -> 1.7559462 | U16: =SUMIFS([1]raw_data!Q:Q,[1]raw_data!$A:$A,$B16) -> 343.02577 | V16: =SUMIFS([1]raw_data!R:R,[1]raw_data!$A:$A,$B16) -> 1.7352637 | W16: =SUMIFS([1]raw_data!S:S,[1]raw_data!$A:$A,$B16) -> 753.34017 | X16: =SUMIFS([1]raw_data!T:T,[1]raw_data!$A:$A,$B16) -> 1.8020022 | Y16: =SUMIFS([1]raw_data!U:U,[1]raw_data!$A:$A,$B16) -> 700.5264 | Z16: =SUMIFS([1]raw_data!V:V,[1]raw_data!$A:$A,$B16) -> 1.7842047 | AA16: =(I16+M16+Q16+U16+Y16)/5 -> 334.12674
B17: 006401 | C17: BEECHER | D17: DISPOSAL | E17: Adrian | F17: =IFERROR(INDEX([1]raw_data!B:B,MATCH('SAIDI excl MEDs sort (5-yr avg)'!B33,[1]raw_data!A:A,0)),0) -> 1418.4 | G17: =SUMIFS([1]raw_data!C:C,[1]raw_data!$A:$A,$B17) -> 3211.0112 | H17: =SUMIFS([1]raw_data!D:D,[1]raw_data!$A:$A,$B17) -> 1.5316901 | I17: =SUMIFS([1]raw_data!E:E,[1]raw_data!$A:$A,$B17) -> 197.27619 | J17: =SUMIFS([1]raw_data!F:F,[1]raw_data!$A:$A,$B17) -> 0.71126761 | K17: =SUMIFS([1]raw_data!G:G,[1]raw_data!$A:$A,$B17) -> 81.064816 | L17: =SUMIFS([1]raw_data!H:H,[1]raw_data!$A:$A,$B17) -> 0.4341637 | M17: =SUMIFS([1]raw_data!I:I,[1]raw_data!$A:$A,$B17) -> 81.064816 | N17: =SUMIFS([1]raw_data!J:J,[1]raw_data!$A:$A,$B17) -> 0.4341637 | O17: =SUMIFS([1]raw_data!K:K,[1]raw_data!$A:$A,$B17) -> 20.28701 | P17: =SUMIFS([1]raw_data!L:L,[1]raw_data!$A:$A,$B17) -> 0.085409253 | Q17: =SUMIFS([1]raw_data!M:M,[1]raw_data!$A:$A,$B17) -> 9.379359 | R17: =SUMIFS([1]raw_data!N:N,[1]raw_data!$A:$A,$B17) -> 0.081850534 | S17: =SUMIFS([1]raw_data!O:O,[1]raw_data!$A:$A,$B17) -> 156.79399 | T17: =SUMIFS([1]raw_data!P:P,[1]raw_data!$A:$A,$B17) -> 1.1214286 | U17: =SUMIFS([1]raw_data!Q:Q,[1]raw_data!$A:$A,$B17) -> 156.51536 | V17: =SUMIFS([1]raw_data!R:R,[1]raw_data!$A:$A,$B17) -> 1.1178571 | W17: =SUMIFS([1]raw_data!S:S,[1]raw_data!$A:$A,$B17) -> 1158.512 | X17: =SUMIFS([1]raw_data!T:T,[1]raw_data!$A:$A,$B17) -> 3.3107143 | Y17: =SUMIFS([1]raw_data!U:U,[1]raw_data!$A:$A,$B17) -> 1158.512 | Z17: =SUMIFS([1]raw_data!V:V,[1]raw_data!$A:$A,$B17) -> 3.3107143 | AA17: =(I17+M17+Q17+U17+Y17)/5 -> 320.54954 | AC17: Muskegon | AD17: =COUNTIF(E4:E40,"Muskegon") -> 4 | AF17: =COUNTIF(E4:E193,"Muskegon") -> 21
B18: 010005 | C18: WEALTHY STREET | D18: WATSON | E18: Grand Rapids | F18: =IFERROR(INDEX([1]raw_data!B:B,MATCH('SAIDI excl MEDs sort (5-yr avg)'!B12,[1]raw_data!A:A,0)),0) -> 115.2 | G18: =SUMIFS([1]raw_data!C:C,[1]raw_data!$A:$A,$B18) -> 372.97109 | H18: =SUMIFS([1]raw_data!D:D,[1]raw_data!$A:$A,$B18) -> 2.8692308 | I18: =SUMIFS([1]raw_data!E:E,[1]raw_data!$A:$A,$B18) -> 372.97109 | J18: =SUMIFS([1]raw_data!F:F,[1]raw_data!$A:$A,$B18) -> 2.8692308 | K18: =SUMIFS([1]raw_data!G:G,[1]raw_data!$A:$A,$B18) -> 642.0812 | L18: =SUMIFS([1]raw_data!H:H,[1]raw_data!$A:$A,$B18) -> 2.8571429 | M18: =SUMIFS([1]raw_data!I:I,[1]raw_data!$A:$A,$B18) -> 642.0812 | N18: =SUMIFS([1]raw_data!J:J,[1]raw_data!$A:$A,$B18) -> 2.8571429 | O18: =SUMIFS([1]raw_data!K:K,[1]raw_data!$A:$A,$B18) -> 242.96371 | P18: =SUMIFS([1]raw_data!L:L,[1]raw_data!$A:$A,$B18) -> 1.0322581 | Q18: =SUMIFS([1]raw_data!M:M,[1]raw_data!$A:$A,$B18) -> 242.96371 | R18: =SUMIFS([1]raw_data!N:N,[1]raw_data!$A:$A,$B18) -> 1.0322581 | S18: =SUMIFS([1]raw_data!O:O,[1]raw_data!$A:$A,$B18) -> 265.76653 | T18: =SUMIFS([1]raw_data!P:P,[1]raw_data!$A:$A,$B18) -> 2.1735537 | U18: =SUMIFS([1]raw_data!Q:Q,[1]raw_data!$A:$A,$B18) -> 265.76653 | V18: =SUMIFS([1]raw_data!R:R,[1]raw_data!$A:$A,$B18) -> 2.1735537 | W18: =SUMIFS([1]raw_data!S:S,[1]raw_data!$A:$A,$B18) -> 30.49537 | X18: =SUMIFS([1]raw_data!T:T,[1]raw_data!$A:$A,$B18) -> 0.12962963 | Y18: =SUMIFS([1]raw_data!U:U,[1]raw_data!$A:$A,$B18) -> 30.49537 | Z18: =SUMIFS([1]raw_data!V:V,[1]raw_data!$A:$A,$B18) -> 0.12962963 | AA18: =(I18+M18+Q18+U18+Y18)/5 -> 310.85558 | AC18: Jackson | AD18: =COUNTIF(E4:E40,"Jackson") -> 0 | AF18: =COUNTIF(E4:E193,"Jackson") -> 13
B19: 039003 | C19: SLOAN | D19: LONGFELLOW | E19: Flint | F19: =IFERROR(INDEX([1]raw_data!B:B,MATCH('SAIDI excl MEDs sort (5-yr avg)'!B112,[1]raw_data!A:A,0)),0) -> 1801.2222 | G19: =SUMIFS([1]raw_data!C:C,[1]raw_data!$A:$A,$B19) -> 754.12927 | H19: =SUMIFS([1]raw_data!D:D,[1]raw_data!$A:$A,$B19) -> 2.3661504 | I19: =SUMIFS([1]raw_data!E:E,[1]raw_data!$A:$A,$B19) -> 29.527079 | J19: =SUMIFS([1]raw_data!F:F,[1]raw_data!$A:$A,$B19) -> 0.11504425 | K19: =SUMIFS([1]raw_data!G:G,[1]raw_data!$A:$A,$B19) -> 1408.6413 | L19: =SUMIFS([1]raw_data!H:H,[1]raw_data!$A:$A,$B19) -> 3.5782123 | M19: =SUMIFS([1]raw_data!I:I,[1]raw_data!$A:$A,$B19) -> 645.20147 | N19: =SUMIFS([1]raw_data!J:J,[1]raw_data!$A:$A,$B19) -> 3.1011173 | O19: =SUMIFS([1]raw_data!K:K,[1]raw_data!$A:$A,$B19) -> 1151.536 | P19: =SUMIFS([1]raw_data!L:L,[1]raw_data!$A:$A,$B19) -> 3.1907159 | Q19: =SUMIFS([1]raw_data!M:M,[1]raw_data!$A:$A,$B19) -> 574.44378 | R19: =SUMIFS([1]raw_data!N:N,[1]raw_data!$A:$A,$B19) -> 2.3836689 | S19: =SUMIFS([1]raw_data!O:O,[1]raw_data!$A:$A,$B19) -> 225.94858 | T19: =SUMIFS([1]raw_data!P:P,[1]raw_data!$A:$A,$B19) -> 0.81412429 | U19: =SUMIFS([1]raw_data!Q:Q,[1]raw_data!$A:$A,$B19) -> 176.40363 | V19: =SUMIFS([1]raw_data!R:R,[1]raw_data!$A:$A,$B19) -> 0.78248588 | W19: =SUMIFS([1]raw_data!S:S,[1]raw_data!$A:$A,$B19) -> 121.85759 | X19: =SUMIFS([1]raw_data!T:T,[1]raw_data!$A:$A,$B19) -> 0.76636051 | Y19: =SUMIFS([1]raw_data!U:U,[1]raw_data!$A:$A,$B19) -> 75.233409 | Z19: =SUMIFS([1]raw_data!V:V,[1]raw_data!$A:$A,$B19) -> 0.70264064 | AA19: =(I19+M19+Q19+U19+Y19)/5 -> 300.16187 | AC19: Adrian | AD19: =COUNTIF(E4:E40,"Adrian") -> 4 | AF19: =COUNTIF(E4:E193,"Adrian") -> 6
B20: 077601 | C20: KEATING | D20: WOOD STREET | E20: Muskegon | F20: =IFERROR(INDEX([1]raw_data!B:B,MATCH('SAIDI excl MEDs sort (5-yr avg)'!B95,[1]raw_data!A:A,0)),0) -> 1140.2 | G20: =SUMIFS([1]raw_data!C:C,[1]raw_data!$A:$A,$B20) -> 307.82751 | H20: =SUMIFS([1]raw_data!D:D,[1]raw_data!$A:$A,$B20) -> 1.3902439 | I20: =SUMIFS([1]raw_data!E:E,[1]raw_data!$A:$A,$B20) -> 47.865195 | J20: =SUMIFS([1]raw_data!F:F,[1]raw_data!$A:$A,$B20) -> 0.55222014 | K20: =SUMIFS([1]raw_data!G:G,[1]raw_data!$A:$A,$B20) -> 54.390947 | L20: =SUMIFS([1]raw_data!H:H,[1]raw_data!$A:$A,$B20) -> 0.43670077 | M20: =SUMIFS([1]raw_data!I:I,[1]raw_data!$A:$A,$B20) -> 51.134147 | N20: =SUMIFS([1]raw_data!J:J,[1]raw_data!$A:$A,$B20) -> 0.43158568 | O20: =SUMIFS([1]raw_data!K:K,[1]raw_data!$A:$A,$B20) -> 329.80128 | P20: =SUMIFS([1]raw_data!L:L,[1]raw_data!$A:$A,$B20) -> 1.3613607 | Q20: =SUMIFS([1]raw_data!M:M,[1]raw_data!$A:$A,$B20) -> 326.21904 | R20: =SUMIFS([1]raw_data!N:N,[1]raw_data!$A:$A,$B20) -> 1.3446727 | S20: =SUMIFS([1]raw_data!O:O,[1]raw_data!$A:$A,$B20) -> 636.05322 | T20: =SUMIFS([1]raw_data!P:P,[1]raw_data!$A:$A,$B20) -> 5.3689633 | U20: =SUMIFS([1]raw_data!Q:Q,[1]raw_data!$A:$A,$B20) -> 633.26833 | V20: =SUMIFS([1]raw_data!R:R,[1]raw_data!$A:$A,$B20) -> 5.3535093 | W20: =SUMIFS([1]raw_data!S:S,[1]raw_data!$A:$A,$B20) -> 748.17709 | X20: =SUMIFS([1]raw_data!T:T,[1]raw_data!$A:$A,$B20) -> 3.4767518 | Y20: =SUMIFS([1]raw_data!U:U,[1]raw_data!$A:$A,$B20) -> 358.96885 | Z20: =SUMIFS([1]raw_data!V:V,[1]raw_data!$A:$A,$B20) -> 2.1604453 | AA20: =(I20+M20+Q20+U20+Y20)/5 -> 283.49111 | AC20: Battle Creek | AD20: =COUNTIF(E4:E40,"Battle Creek") -> 3 | AF20: =COUNTIF(E4:E193,"Battle Creek") -> 11
B21: 054804 | C21: LEONARD | D21: NEWBERRY | E21: Grand Rapids | F21: =IFERROR(INDEX([1]raw_data!B:B,MATCH('SAIDI excl MEDs sort (5-yr avg)'!B78,[1]raw_data!A:A,0)),0) -> 810.11111 | G21: =SUMIFS([1]raw_data!C:C,[1]raw_data!$A:$A,$B21) -> 75.388832 | H21: =SUMIFS([1]raw_data!D:D,[1]raw_data!$A:$A,$B21) -> 0.98727273 | I21: =SUMIFS([1]raw_data!E:E,[1]raw_data!$A:$A,$B21) -> 75.317213 | J21: =SUMIFS([1]raw_data!F:F,[1]raw_data!$A:$A,$B21) -> 0.98545455 | K21: =SUMIFS([1]raw_data!G:G,[1]raw_data!$A:$A,$B21) -> 1964.8346 | L21: =SUMIFS([1]raw_data!H:H,[1]raw_data!$A:$A,$B21) -> 2.8378378 | M21: =SUMIFS([1]raw_data!I:I,[1]raw_data!$A:$A,$B21) -> 774.96845 | N21: =SUMIFS([1]raw_data!J:J,[1]raw_data!$A:$A,$B21) -> 1.9225225 | O21: =SUMIFS([1]raw_data!K:K,[1]raw_data!$A:$A,$B21) -> 236.29394 | P21: =SUMIFS([1]raw_data!L:L,[1]raw_data!$A:$A,$B21) -> 2.9118705 | Q21: =SUMIFS([1]raw_data!M:M,[1]raw_data!$A:$A,$B21) -> 231.52926 | R21: =SUMIFS([1]raw_data!N:N,[1]raw_data!$A:$A,$B21) -> 2.9082734 | S21: =SUMIFS([1]raw_data!O:O,[1]raw_data!$A:$A,$B21) -> 269.82518 | T21: =SUMIFS([1]raw_data!P:P,[1]raw_data!$A:$A,$B21) -> 3.115942 | U21: =SUMIFS([1]raw_data!Q:Q,[1]raw_data!$A:$A,$B21) -> 269.82518 | V21: =SUMIFS([1]raw_data!R:R,[1]raw_data!$A:$A,$B21) -> 3.115942 | W21: =SUMIFS([1]raw_data!S:S,[1]raw_data!$A:$A,$B21) -> 19.616042 | X21: =SUMIFS([1]raw_data!T:T,[1]raw_data!$A:$A,$B21) -> 0.048689139 | Y21: =SUMIFS([1]raw_data!U:U,[1]raw_data!$A:$A,$B21) -> 19.616042 | Z21: =SUMIFS([1]raw_data!V:V,[1]raw_data!$A:$A,$B21) -> 0.048689139 | AA21: =(I21+M21+Q21+U21+Y21)/5 -> 274.25123 | AC21: Kalamazoo | AD21: =COUNTIF(E4:E40,"Kalamazoo") -> 5 | AF21: =COUNTIF(E4:E193,"Kalamazoo") -> 31
B22: 003902 | C22: MAUMEE | D22: LENAWEE ST | E22: Adrian | F22: =IFERROR(INDEX([1]raw_data!B:B,MATCH('SAIDI excl MEDs sort (5-yr avg)'!B99,[1]raw_data!A:A,0)),0) -> 1514.8 | G22: =SUMIFS([1]raw_data!C:C,[1]raw_data!$A:$A,$B22) -> 5540.9072 | H22: =SUMIFS([1]raw_data!D:D,[1]raw_data!$A:$A,$B22) -> 1.684507 | I22: =SUMIFS([1]raw_data!E:E,[1]raw_data!$A:$A,$B22) -> 45.11083 | J22: =SUMIFS([1]raw_data!F:F,[1]raw_data!$A:$A,$B22) -> 0.66830986 | K22: =SUMIFS([1]raw_data!G:G,[1]raw_data!$A:$A,$B22) -> 869.58842 | L22: =SUMIFS([1]raw_data!H:H,[1]raw_data!$A:$A,$B22) -> 3.0140056 | M22: =SUMIFS([1]raw_data!I:I,[1]raw_data!$A:$A,$B22) -> 120.40631 | N22: =SUMIFS([1]raw_data!J:J,[1]raw_data!$A:$A,$B22) -> 1.3970588 | O22: =SUMIFS([1]raw_data!K:K,[1]raw_data!$A:$A,$B22) -> 551.84509 | P22: =SUMIFS([1]raw_data!L:L,[1]raw_data!$A:$A,$B22) -> 3.1547117 | Q22: =SUMIFS([1]raw_data!M:M,[1]raw_data!$A:$A,$B22) -> 183.48197 | R22: =SUMIFS([1]raw_data!N:N,[1]raw_data!$A:$A,$B22) -> 2.1540084 | S22: =SUMIFS([1]raw_data!O:O,[1]raw_data!$A:$A,$B22) -> 121.56555 | T22: =SUMIFS([1]raw_data!P:P,[1]raw_data!$A:$A,$B22) -> 1.7986014 | U22: =SUMIFS([1]raw_data!Q:Q,[1]raw_data!$A:$A,$B22) -> 120.98495 | V22: =SUMIFS([1]raw_data!R:R,[1]raw_data!$A:$A,$B22) -> 1.7699301 | W22: =SUMIFS([1]raw_data!S:S,[1]raw_data!$A:$A,$B22) -> 892.23187 | X22: =SUMIFS([1]raw_data!T:T,[1]raw_data!$A:$A,$B22) -> 2.2251235 | Y22: =SUMIFS([1]raw_data!U:U,[1]raw_data!$A:$A,$B22) -> 891.73432 | Z22: =SUMIFS([1]raw_data!V:V,[1]raw_data!$A:$A,$B22) -> 2.2244178 | AA22: =(I22+M22+Q22+U22+Y22)/5 -> 272.34368 | AC22: Flint | AD22: =COUNTIF(E4:E40,"Flint") -> 10 | AF22: =COUNTIF(E4:E193,"Flint") -> 42
B23: 090601 | C23: HARRIET | D23: WITHERBEE | E23: Flint | F23: =IFERROR(INDEX([1]raw_data!B:B,MATCH('SAIDI excl MEDs sort (5-yr avg)'!B151,[1]raw_data!A:A,0)),0) -> 48.25 | G23: =SUMIFS([1]raw_data!C:C,[1]raw_data!$A:$A,$B23) -> 4.643464 | H23: =SUMIFS([1]raw_data!D:D,[1]raw_data!$A:$A,$B23) -> 0.009569378 | I23: =SUMIFS([1]raw_data!E:E,[1]raw_data!$A:$A,$B23) -> 4.643464 | J23: =SUMIFS([1]raw_data!F:F,[1]raw_data!$A:$A,$B23) -> 0.009569378 | K23: =SUMIFS([1]raw_data!G:G,[1]raw_data!$A:$A,$B23) -> 372.71669 | L23: =SUMIFS([1]raw_data!H:H,[1]raw_data!$A:$A,$B23) -> 1.0240096 | M23: =SUMIFS([1]raw_data!I:I,[1]raw_data!$A:$A,$B23) -> 372.71669 | N23: =SUMIFS([1]raw_data!J:J,[1]raw_data!$A:$A,$B23) -> 1.0240096 | O23: =SUMIFS([1]raw_data!K:K,[1]raw_data!$A:$A,$B23) -> 467.58828 | P23: =SUMIFS([1]raw_data!L:L,[1]raw_data!$A:$A,$B23) -> 1.5741627 | Q23: =SUMIFS([1]raw_data!M:M,[1]raw_data!$A:$A,$B23) -> 465.26314 | R23: =SUMIFS([1]raw_data!N:N,[1]raw_data!$A:$A,$B23) -> 1.5717703 | S23: =SUMIFS([1]raw_data!O:O,[1]raw_data!$A:$A,$B23) -> 94.243662 | T23: =SUMIFS([1]raw_data!P:P,[1]raw_data!$A:$A,$B23) -> 0.83996463 | U23: =SUMIFS([1]raw_data!Q:Q,[1]raw_data!$A:$A,$B23) -> 45.957264 | V23: =SUMIFS([1]raw_data!R:R,[1]raw_data!$A:$A,$B23) -> 0.069849691 | W23: =SUMIFS([1]raw_data!S:S,[1]raw_data!$A:$A,$B23) -> 468.30378 | X23: =SUMIFS([1]raw_data!T:T,[1]raw_data!$A:$A,$B23) -> 2.3314045 | Y23: =SUMIFS([1]raw_data!U:U,[1]raw_data!$A:$A,$B23) -> 467.35641 | Z23: =SUMIFS([1]raw_data!V:V,[1]raw_data!$A:$A,$B23) -> 2.3303524 | AA23: =(I23+M23+Q23+U23+Y23)/5 -> 271.18739 | AC23: Grand Rapids | AD23: =COUNTIF(E4:E40,"Grand Rapids") -> 11 | AF23: =COUNTIF(E4:E193,"Grand Rapids") -> 66
B24: 079301 | C24: RAVINE | D24: PATTERSON | E24: Kalamazoo | F24: =IFERROR(INDEX([1]raw_data!B:B,MATCH('SAIDI excl MEDs sort (5-yr avg)'!B53,[1]raw_data!A:A,0)),0) -> 1705.2 | G24: =SUMIFS([1]raw_data!C:C,[1]raw_data!$A:$A,$B24) -> 607.41873 | H24: =SUMIFS([1]raw_data!D:D,[1]raw_data!$A:$A,$B24) -> 2.1030685 | I24: =SUMIFS([1]raw_data!E:E,[1]raw_data!$A:$A,$B24) -> 135.21228 | J24: =SUMIFS([1]raw_data!F:F,[1]raw_data!$A:$A,$B24) -> 1.097561 | K24: =SUMIFS([1]raw_data!G:G,[1]raw_data!$A:$A,$B24) -> 175.69006 | L24: =SUMIFS([1]raw_data!H:H,[1]raw_data!$A:$A,$B24) -> 0.80769231 | M24: =SUMIFS([1]raw_data!I:I,[1]raw_data!$A:$A,$B24) -> 175.69006 | N24: =SUMIFS([1]raw_data!J:J,[1]raw_data!$A:$A,$B24) -> 0.80769231 | O24: =SUMIFS([1]raw_data!K:K,[1]raw_data!$A:$A,$B24) -> 312.13924 | P24: =SUMIFS([1]raw_data!L:L,[1]raw_data!$A:$A,$B24) -> 2.3518809 | Q24: =SUMIFS([1]raw_data!M:M,[1]raw_data!$A:$A,$B24) -> 302.48627 | R24: =SUMIFS([1]raw_data!N:N,[1]raw_data!$A:$A,$B24) -> 2.3424765 | S24: =SUMIFS([1]raw_data!O:O,[1]raw_data!$A:$A,$B24) -> 654.56798 | T24: =SUMIFS([1]raw_data!P:P,[1]raw_data!$A:$A,$B24) -> 1.8066724 | U24: =SUMIFS([1]raw_data!Q:Q,[1]raw_data!$A:$A,$B24) -> 654.56798 | V24: =SUMIFS([1]raw_data!R:R,[1]raw_data!$A:$A,$B24) -> 1.8066724 | W24: =SUMIFS([1]raw_data!S:S,[1]raw_data!$A:$A,$B24) -> 220.96455 | X24: =SUMIFS([1]raw_data!T:T,[1]raw_data!$A:$A,$B24) -> 0.86248013 | Y24: =SUMIFS([1]raw_data!U:U,[1]raw_data!$A:$A,$B24) -> 72.445482 | Z24: =SUMIFS([1]raw_data!V:V,[1]raw_data!$A:$A,$B24) -> 0.57631161 | AA24: =(I24+M24+Q24+U24+Y24)/5 -> 268.08041
B25: 032502 | C25: BOSTON SQUARE | D25: KALAMAZOO | E25: Grand Rapids | F25: =IFERROR(INDEX([1]raw_data!B:B,MATCH('SAIDI excl MEDs sort (5-yr avg)'!B134,[1]raw_data!A:A,0)),0) -> 516.625 | G25: =SUMIFS([1]raw_data!C:C,[1]raw_data!$A:$A,$B25) -> 12.160321 | H25: =SUMIFS([1]raw_data!D:D,[1]raw_data!$A:$A,$B25) -> 0.10393802 | I25: =SUMIFS([1]raw_data!E:E,[1]raw_data!$A:$A,$B25) -> 11.836369 | J25: =SUMIFS([1]raw_data!F:F,[1]raw_data!$A:$A,$B25) -> 0.10329245 | K25: =SUMIFS([1]raw_data!G:G,[1]raw_data!$A:$A,$B25) -> 583.13712 | L25: =SUMIFS([1]raw_data!H:H,[1]raw_data!$A:$A,$B25) -> 1.20245 | M25: =SUMIFS([1]raw_data!I:I,[1]raw_data!$A:$A,$B25) -> 575.11156 | N25: =SUMIFS([1]raw_data!J:J,[1]raw_data!$A:$A,$B25) -> 1.1553836 | O25: =SUMIFS([1]raw_data!K:K,[1]raw_data!$A:$A,$B25) -> 606.35235 | P25: =SUMIFS([1]raw_data!L:L,[1]raw_data!$A:$A,$B25) -> 4.1008403 | Q25: =SUMIFS([1]raw_data!M:M,[1]raw_data!$A:$A,$B25) -> 604.00853 | R25: =SUMIFS([1]raw_data!N:N,[1]raw_data!$A:$A,$B25) -> 4.0982547 | S25: =SUMIFS([1]raw_data!O:O,[1]raw_data!$A:$A,$B25) -> 75.03228 | T25: =SUMIFS([1]raw_data!P:P,[1]raw_data!$A:$A,$B25) -> 0.56742671 | U25: =SUMIFS([1]raw_data!Q:Q,[1]raw_data!$A:$A,$B25) -> 75.03228 | V25: =SUMIFS([1]raw_data!R:R,[1]raw_data!$A:$A,$B25) -> 0.56742671 | W25: =SUMIFS([1]raw_data!S:S,[1]raw_data!$A:$A,$B25) -> 1754.2377 | X25: =SUMIFS([1]raw_data!T:T,[1]raw_data!$A:$A,$B25) -> 1.0026042 | Y25: =SUMIFS([1]raw_data!U:U,[1]raw_data!$A:$A,$B25) -> 32.683832 | Z25: =SUMIFS([1]raw_data!V:V,[1]raw_data!$A:$A,$B25) -> 0.31966146 | AA25: =(I25+M25+Q25+U25+Y25)/5 -> 259.73452
B26: 040401 | C26: ALBER | D26: TERRITORIAL | E26: Battle Creek | F26: =IFERROR(INDEX([1]raw_data!B:B,MATCH('SAIDI excl MEDs sort (5-yr avg)'!B69,[1]raw_data!A:A,0)),0) -> 329.375 | G26: =SUMIFS([1]raw_data!C:C,[1]raw_data!$A:$A,$B26) -> 1245.6575 | H26: =SUMIFS([1]raw_data!D:D,[1]raw_data!$A:$A,$B26) -> 1.2261209 | I26: =SUMIFS([1]raw_data!E:E,[1]raw_data!$A:$A,$B26) -> 93.936811 | J26: =SUMIFS([1]raw_data!F:F,[1]raw_data!$A:$A,$B26) -> 0.27095517 | K26: =SUMIFS([1]raw_data!G:G,[1]raw_data!$A:$A,$B26) -> 558.99963 | L26: =SUMIFS([1]raw_data!H:H,[1]raw_data!$A:$A,$B26) -> 1.9682437 | M26: =SUMIFS([1]raw_data!I:I,[1]raw_data!$A:$A,$B26) -> 558.36289 | N26: =SUMIFS([1]raw_data!J:J,[1]raw_data!$A:$A,$B26) -> 1.9669475 | O26: =SUMIFS([1]raw_data!K:K,[1]raw_data!$A:$A,$B26) -> 167.88277 | P26: =SUMIFS([1]raw_data!L:L,[1]raw_data!$A:$A,$B26) -> 0.13195343 | Q26: =SUMIFS([1]raw_data!M:M,[1]raw_data!$A:$A,$B26) -> 3.984659 | R26: =SUMIFS([1]raw_data!N:N,[1]raw_data!$A:$A,$B26) -> 0.038809832 | S26: =SUMIFS([1]raw_data!O:O,[1]raw_data!$A:$A,$B26) -> 4975.4824 | T26: =SUMIFS([1]raw_data!P:P,[1]raw_data!$A:$A,$B26) -> 4.1679715 | U26: =SUMIFS([1]raw_data!Q:Q,[1]raw_data!$A:$A,$B26) -> 301.3379 | V26: =SUMIFS([1]raw_data!R:R,[1]raw_data!$A:$A,$B26) -> 3.0754448 | W26: =SUMIFS([1]raw_data!S:S,[1]raw_data!$A:$A,$B26) -> 340.95894 | X26: =SUMIFS([1]raw_data!T:T,[1]raw_data!$A:$A,$B26) -> 2.1716907 | Y26: =SUMIFS([1]raw_data!U:U,[1]raw_data!$A:$A,$B26) -> 329.19526 | Z26: =SUMIFS([1]raw_data!V:V,[1]raw_data!$A:$A,$B26) -> 2.1120577 | AA26: =(I26+M26+Q26+U26+Y26)/5 -> 257.3635
B27: 058601 | C27: LEITH STREET | D27: FRANKLIN | E27: Flint | F27: =IFERROR(INDEX([1]raw_data!B:B,MATCH('SAIDI excl MEDs sort (5-yr avg)'!B137,[1]raw_data!A:A,0)),0) -> 395.57143 | G27: =SUMIFS([1]raw_data!C:C,[1]raw_data!$A:$A,$B27) -> 10.492841 | H27: =SUMIFS([1]raw_data!D:D,[1]raw_data!$A:$A,$B27) -> 0.099363057 | I27: =SUMIFS([1]raw_data!E:E,[1]raw_data!$A:$A,$B27) -> 10.492841 | J27: =SUMIFS([1]raw_data!F:F,[1]raw_data!$A:$A,$B27) -> 0.099363057 | K27: =SUMIFS([1]raw_data!G:G,[1]raw_data!$A:$A,$B27) -> 31.970343 | L27: =SUMIFS([1]raw_data!H:H,[1]raw_data!$A:$A,$B27) -> 0.17758186 | M27: =SUMIFS([1]raw_data!I:I,[1]raw_data!$A:$A,$B27) -> 31.107384 | N27: =SUMIFS([1]raw_data!J:J,[1]raw_data!$A:$A,$B27) -> 0.17506297 | O27: =SUMIFS([1]raw_data!K:K,[1]raw_data!$A:$A,$B27) -> 1292.1658 | P27: =SUMIFS([1]raw_data!L:L,[1]raw_data!$A:$A,$B27) -> 1.3588457 | Q27: =SUMIFS([1]raw_data!M:M,[1]raw_data!$A:$A,$B27) -> 695.47685 | R27: =SUMIFS([1]raw_data!N:N,[1]raw_data!$A:$A,$B27) -> 1.1819322 | S27: =SUMIFS([1]raw_data!O:O,[1]raw_data!$A:$A,$B27) -> 68.656853 | T27: =SUMIFS([1]raw_data!P:P,[1]raw_data!$A:$A,$B27) -> 0.28518972 | U27: =SUMIFS([1]raw_data!Q:Q,[1]raw_data!$A:$A,$B27) -> 68.54596 | V27: =SUMIFS([1]raw_data!R:R,[1]raw_data!$A:$A,$B27) -> 0.28151775 | W27: =SUMIFS([1]raw_data!S:S,[1]raw_data!$A:$A,$B27) -> 462.21706 | X27: =SUMIFS([1]raw_data!T:T,[1]raw_data!$A:$A,$B27) -> 1.3739546 | Y27: =SUMIFS([1]raw_data!U:U,[1]raw_data!$A:$A,$B27) -> 454.54532 | Z27: =SUMIFS([1]raw_data!V:V,[1]raw_data!$A:$A,$B27) -> 1.3524492 | AA27: =(I27+M27+Q27+U27+Y27)/5 -> 252.03367
B28: 074304 | C28: RED ARROW | D28: OGEMA | E28: Flint | F28: =IFERROR(INDEX([1]raw_data!B:B,MATCH('SAIDI excl MEDs sort (5-yr avg)'!B11,[1]raw_data!A:A,0)),0) -> 788 | G28: =SUMIFS([1]raw_data!C:C,[1]raw_data!$A:$A,$B28) -> 388.23441 | H28: =SUMIFS([1]raw_data!D:D,[1]raw_data!$A:$A,$B28) -> 1.3366398 | I28: =SUMIFS([1]raw_data!E:E,[1]raw_data!$A:$A,$B28) -> 388.05711 | J28: =SUMIFS([1]raw_data!F:F,[1]raw_data!$A:$A,$B28) -> 1.3360198 | K28: =SUMIFS([1]raw_data!G:G,[1]raw_data!$A:$A,$B28) -> 640.90034 | L28: =SUMIFS([1]raw_data!H:H,[1]raw_data!$A:$A,$B28) -> 1.408125 | M28: =SUMIFS([1]raw_data!I:I,[1]raw_data!$A:$A,$B28) -> 36.214118 | N28: =SUMIFS([1]raw_data!J:J,[1]raw_data!$A:$A,$B28) -> 0.256875 | O28: =SUMIFS([1]raw_data!K:K,[1]raw_data!$A:$A,$B28) -> 40.338625 | P28: =SUMIFS([1]raw_data!L:L,[1]raw_data!$A:$A,$B28) -> 0.19785759 | Q28: =SUMIFS([1]raw_data!M:M,[1]raw_data!$A:$A,$B28) -> 37.720121 | R28: =SUMIFS([1]raw_data!N:N,[1]raw_data!$A:$A,$B28) -> 0.1915564 | S28: =SUMIFS([1]raw_data!O:O,[1]raw_data!$A:$A,$B28) -> 685.48292 | T28: =SUMIFS([1]raw_data!P:P,[1]raw_data!$A:$A,$B28) -> 3.45335 | U28: =SUMIFS([1]raw_data!Q:Q,[1]raw_data!$A:$A,$B28) -> 684.02721 | V28: =SUMIFS([1]raw_data!R:R,[1]raw_data!$A:$A,$B28) -> 3.4458359 | W28: =SUMIFS([1]raw_data!S:S,[1]raw_data!$A:$A,$B28) -> 106.38029 | X28: =SUMIFS([1]raw_data!T:T,[1]raw_data!$A:$A,$B28) -> 0.34779874 | Y28: =SUMIFS([1]raw_data!U:U,[1]raw_data!$A:$A,$B28) -> 90.235796 | Z28: =SUMIFS([1]raw_data!V:V,[1]raw_data!$A:$A,$B28) -> 0.31698113 | AA28: =(I28+M28+Q28+U28+Y28)/5 -> 247.25087
B29: 077401 | C29: DEWEY | D29: WIDDICOMB | E29: Grand Rapids | F29: =IFERROR(INDEX([1]raw_data!B:B,MATCH('SAIDI excl MEDs sort (5-yr avg)'!B19,[1]raw_data!A:A,0)),0) -> 1598.8 | G29: =SUMIFS([1]raw_data!C:C,[1]raw_data!$A:$A,$B29) -> 287.6085 | H29: =SUMIFS([1]raw_data!D:D,[1]raw_data!$A:$A,$B29) -> 1.1306533 | I29: =SUMIFS([1]raw_data!E:E,[1]raw_data!$A:$A,$B29) -> 287.10177 | J29: =SUMIFS([1]raw_data!F:F,[1]raw_data!$A:$A,$B29) -> 1.1286432 | K29: =SUMIFS([1]raw_data!G:G,[1]raw_data!$A:$A,$B29) -> 1690.6742 | L29: =SUMIFS([1]raw_data!H:H,[1]raw_data!$A:$A,$B29) -> 4.4883721 | M29: =SUMIFS([1]raw_data!I:I,[1]raw_data!$A:$A,$B29) -> 337.15799 | N29: =SUMIFS([1]raw_data!J:J,[1]raw_data!$A:$A,$B29) -> 2.8129845 | O29: =SUMIFS([1]raw_data!K:K,[1]raw_data!$A:$A,$B29) -> 95.41006 | P29: =SUMIFS([1]raw_data!L:L,[1]raw_data!$A:$A,$B29) -> 1.1463178 | Q29: =SUMIFS([1]raw_data!M:M,[1]raw_data!$A:$A,$B29) -> 14.249337 | R29: =SUMIFS([1]raw_data!N:N,[1]raw_data!$A:$A,$B29) -> 0.11143411 | S29: =SUMIFS([1]raw_data!O:O,[1]raw_data!$A:$A,$B29) -> 588.12784 | T29: =SUMIFS([1]raw_data!P:P,[1]raw_data!$A:$A,$B29) -> 2.0107991 | U29: =SUMIFS([1]raw_data!Q:Q,[1]raw_data!$A:$A,$B29) -> 548.74258 | V29: =SUMIFS([1]raw_data!R:R,[1]raw_data!$A:$A,$B29) -> 1.9838013 | W29: =SUMIFS([1]raw_data!S:S,[1]raw_data!$A:$A,$B29) -> 18.152516 | X29: =SUMIFS([1]raw_data!T:T,[1]raw_data!$A:$A,$B29) -> 0.14744352 | Y29: =SUMIFS([1]raw_data!U:U,[1]raw_data!$A:$A,$B29) -> 16.958997 | Z29: =SUMIFS([1]raw_data!V:V,[1]raw_data!$A:$A,$B29) -> 0.14387634 | AA29: =(I29+M29+Q29+U29+Y29)/5 -> 240.84213
B30: 041301 | C30: TERRACE | D30: SHORELINE | E30: Muskegon | F30: =IFERROR(INDEX([1]raw_data!B:B,MATCH('SAIDI excl MEDs sort (5-yr avg)'!B46,[1]raw_data!A:A,0)),0) -> 89.5 | G30: =SUMIFS([1]raw_data!C:C,[1]raw_data!$A:$A,$B30) -> 150.64737 | H30: =SUMIFS([1]raw_data!D:D,[1]raw_data!$A:$A,$B30) -> 1.5044248 | I30: =SUMIFS([1]raw_data!E:E,[1]raw_data!$A:$A,$B30) -> 150.64737 | J30: =SUMIFS([1]raw_data!F:F,[1]raw_data!$A:$A,$B30) -> 1.5044248 | K30: =SUMIFS([1]raw_data!G:G,[1]raw_data!$A:$A,$B30) -> 496.76308 | L30: =SUMIFS([1]raw_data!H:H,[1]raw_data!$A:$A,$B30) -> 1 | M30: =SUMIFS([1]raw_data!I:I,[1]raw_data!$A:$A,$B30) -> 496.76308 | N30: =SUMIFS([1]raw_data!J:J,[1]raw_data!$A:$A,$B30) -> 1 | O30: =SUMIFS([1]raw_data!K:K,[1]raw_data!$A:$A,$B30) -> 684.31206 | P30: =SUMIFS([1]raw_data!L:L,[1]raw_data!$A:$A,$B30) -> 2.8190476 | Q30: =SUMIFS([1]raw_data!M:M,[1]raw_data!$A:$A,$B30) -> 454.89778 | R30: =SUMIFS([1]raw_data!N:N,[1]raw_data!$A:$A,$B30) -> 1.8095238 | S30: =SUMIFS([1]raw_data!O:O,[1]raw_data!$A:$A,$B30) -> 83.455673 | T30: =SUMIFS([1]raw_data!P:P,[1]raw_data!$A:$A,$B30) -> 0.44680851 | U30: =SUMIFS([1]raw_data!Q:Q,[1]raw_data!$A:$A,$B30) -> 83.455673 | V30: =SUMIFS([1]raw_data!R:R,[1]raw_data!$A:$A,$B30) -> 0.44680851 | W30: =SUMIFS([1]raw_data!S:S,[1]raw_data!$A:$A,$B30) -> 525.13493 | X30: =SUMIFS([1]raw_data!T:T,[1]raw_data!$A:$A,$B30) -> 0.47945205 | Y30: =SUMIFS([1]raw_data!U:U,[1]raw_data!$A:$A,$B30) -> 11.902054 | Z30: =SUMIFS([1]raw_data!V:V,[1]raw_data!$A:$A,$B30) -> 0.12328767 | AA30: =(I30+M30+Q30+U30+Y30)/5 -> 239.53319
B31: 041503 | C31: GLENDALE | D31: HERCULES | E31: Kalamazoo | F31: =IFERROR(INDEX([1]raw_data!B:B,MATCH('SAIDI excl MEDs sort (5-yr avg)'!B29,[1]raw_data!A:A,0)),0) -> 965.2 | G31: =SUMIFS([1]raw_data!C:C,[1]raw_data!$A:$A,$B31) -> 1232.9432 | H31: =SUMIFS([1]raw_data!D:D,[1]raw_data!$A:$A,$B31) -> 1.3531073 | I31: =SUMIFS([1]raw_data!E:E,[1]raw_data!$A:$A,$B31) -> 225.47009 | J31: =SUMIFS([1]raw_data!F:F,[1]raw_data!$A:$A,$B31) -> 0.96327684 | K31: =SUMIFS([1]raw_data!G:G,[1]raw_data!$A:$A,$B31) -> 187.56985 | L31: =SUMIFS([1]raw_data!H:H,[1]raw_data!$A:$A,$B31) -> 0.70774977 | M31: =SUMIFS([1]raw_data!I:I,[1]raw_data!$A:$A,$B31) -> 173.61753 | N31: =SUMIFS([1]raw_data!J:J,[1]raw_data!$A:$A,$B31) -> 0.67320261 | O31: =SUMIFS([1]raw_data!K:K,[1]raw_data!$A:$A,$B31) -> 1224.997 | P31: =SUMIFS([1]raw_data!L:L,[1]raw_data!$A:$A,$B31) -> 2.8115672 | Q31: =SUMIFS([1]raw_data!M:M,[1]raw_data!$A:$A,$B31) -> 179.12047 | R31: =SUMIFS([1]raw_data!N:N,[1]raw_data!$A:$A,$B31) -> 1.7873134 | S31: =SUMIFS([1]raw_data!O:O,[1]raw_data!$A:$A,$B31) -> 367.10895 | T31: =SUMIFS([1]raw_data!P:P,[1]raw_data!$A:$A,$B31) -> 1.4519141 | U31: =SUMIFS([1]raw_data!Q:Q,[1]raw_data!$A:$A,$B31) -> 367.10895 | V31: =SUMIFS([1]raw_data!R:R,[1]raw_data!$A:$A,$B31) -> 1.4519141 | W31: =SUMIFS([1]raw_data!S:S,[1]raw_data!$A:$A,$B31) -> 377.86596 | X31: =SUMIFS([1]raw_data!T:T,[1]raw_data!$A:$A,$B31) -> 2.0805556 | Y31: =SUMIFS([1]raw_data!U:U,[1]raw_data!$A:$A,$B31) -> 248.16835 | Z31: =SUMIFS([1]raw_data!V:V,[1]raw_data!$A:$A,$B31) -> 1.0490741 | AA31: =(I31+M31+Q31+U31+Y31)/5 -> 238.69708
B32: 006107 | C32: SAGINAW STREET | D32: LEWIS STREET | E32: Flint | F32: =IFERROR(INDEX([1]raw_data!B:B,MATCH('SAIDI excl MEDs sort (5-yr avg)'!B76,[1]raw_data!A:A,0)),0) -> 1070 | G32: =SUMIFS([1]raw_data!C:C,[1]raw_data!$A:$A,$B32) -> 78.823547 | H32: =SUMIFS([1]raw_data!D:D,[1]raw_data!$A:$A,$B32) -> 0.61788618 | I32: =SUMIFS([1]raw_data!E:E,[1]raw_data!$A:$A,$B32) -> 78.823547 | J32: =SUMIFS([1]raw_data!F:F,[1]raw_data!$A:$A,$B32) -> 0.61788618 | K32: =SUMIFS([1]raw_data!G:G,[1]raw_data!$A:$A,$B32) -> 0 | L32: =SUMIFS([1]raw_data!H:H,[1]raw_data!$A:$A,$B32) -> 0 | M32: =SUMIFS([1]raw_data!I:I,[1]raw_data!$A:$A,$B32) -> 0 | N32: =SUMIFS([1]raw_data!J:J,[1]raw_data!$A:$A,$B32) -> 0 | O32: =SUMIFS([1]raw_data!K:K,[1]raw_data!$A:$A,$B32) -> 1037.1703 | P32: =SUMIFS([1]raw_data!L:L,[1]raw_data!$A:$A,$B32) -> 1.192 | Q32: =SUMIFS([1]raw_data!M:M,[1]raw_data!$A:$A,$B32) -> 1037.1703 | R32: =SUMIFS([1]raw_data!N:N,[1]raw_data!$A:$A,$B32) -> 1.192 | S32: =SUMIFS([1]raw_data!O:O,[1]raw_data!$A:$A,$B32) -> 56.348611 | T32: =SUMIFS([1]raw_data!P:P,[1]raw_data!$A:$A,$B32) -> 1.0916667 | U32: =SUMIFS([1]raw_data!Q:Q,[1]raw_data!$A:$A,$B32) -> 6.748611 | V32: =SUMIFS([1]raw_data!R:R,[1]raw_data!$A:$A,$B32) -> 0.058333333 | W32: =SUMIFS([1]raw_data!S:S,[1]raw_data!$A:$A,$B32) -> 26.214678 | X32: =SUMIFS([1]raw_data!T:T,[1]raw_data!$A:$A,$B32) -> 0.83486239 | Y32: =SUMIFS([1]raw_data!U:U,[1]raw_data!$A:$A,$B32) -> 26.214678 | Z32: =SUMIFS([1]raw_data!V:V,[1]raw_data!$A:$A,$B32) -> 0.83486239 | AA32: =(I32+M32+Q32+U32+Y32)/5 -> 229.79142
B33: 075701 | C33: MAPLE GROVE | D33: HENRY STREET | E33: Muskegon | F33: =IFERROR(INDEX([1]raw_data!B:B,MATCH('SAIDI excl MEDs sort (5-yr avg)'!B7,[1]raw_data!A:A,0)),0) -> 766.22222 | G33: =SUMIFS([1]raw_data!C:C,[1]raw_data!$A:$A,$B33) -> 1140.1991 | H33: =SUMIFS([1]raw_data!D:D,[1]raw_data!$A:$A,$B33) -> 3.6631579 | I33: =SUMIFS([1]raw_data!E:E,[1]raw_data!$A:$A,$B33) -> 652.81186 | J33: =SUMIFS([1]raw_data!F:F,[1]raw_data!$A:$A,$B33) -> 2.5052632 | K33: =SUMIFS([1]raw_data!G:G,[1]raw_data!$A:$A,$B33) -> 52.310887 | L33: =SUMIFS([1]raw_data!H:H,[1]raw_data!$A:$A,$B33) -> 0.29073034 | M33: =SUMIFS([1]raw_data!I:I,[1]raw_data!$A:$A,$B33) -> 51.466569 | N33: =SUMIFS([1]raw_data!J:J,[1]raw_data!$A:$A,$B33) -> 0.2886236 | O33: =SUMIFS([1]raw_data!K:K,[1]raw_data!$A:$A,$B33) -> 54.559361 | P33: =SUMIFS([1]raw_data!L:L,[1]raw_data!$A:$A,$B33) -> 0.34390416 | Q33: =SUMIFS([1]raw_data!M:M,[1]raw_data!$A:$A,$B33) -> 54.330256 | R33: =SUMIFS([1]raw_data!N:N,[1]raw_data!$A:$A,$B33) -> 0.33967583 | S33: =SUMIFS([1]raw_data!O:O,[1]raw_data!$A:$A,$B33) -> 278.94603 | T33: =SUMIFS([1]raw_data!P:P,[1]raw_data!$A:$A,$B33) -> 1.5201129 | U33: =SUMIFS([1]raw_data!Q:Q,[1]raw_data!$A:$A,$B33) -> 278.82997 | V33: =SUMIFS([1]raw_data!R:R,[1]raw_data!$A:$A,$B33) -> 1.51729 | W33: =SUMIFS([1]raw_data!S:S,[1]raw_data!$A:$A,$B33) -> 343.45012 | X33: =SUMIFS([1]raw_data!T:T,[1]raw_data!$A:$A,$B33) -> 0.57356077 | Y33: =SUMIFS([1]raw_data!U:U,[1]raw_data!$A:$A,$B33) -> 108.27496 | Z33: =SUMIFS([1]raw_data!V:V,[1]raw_data!$A:$A,$B33) -> 0.3880597 | AA33: =(I33+M33+Q33+U33+Y33)/5 -> 229.14272
B34: 036002 | C34: LIBERTY | D34: HAMBLIN | E34: Battle Creek | F34: =IFERROR(INDEX([1]raw_data!B:B,MATCH('SAIDI excl MEDs sort (5-yr avg)'!B58,[1]raw_data!A:A,0)),0) -> 651.6 | G34: =SUMIFS([1]raw_data!C:C,[1]raw_data!$A:$A,$B34) -> 298.47822 | H34: =SUMIFS([1]raw_data!D:D,[1]raw_data!$A:$A,$B34) -> 1.4967427 | I34: =SUMIFS([1]raw_data!E:E,[1]raw_data!$A:$A,$B34) -> 118.30961 | J34: =SUMIFS([1]raw_data!F:F,[1]raw_data!$A:$A,$B34) -> 1.0602606 | K34: =SUMIFS([1]raw_data!G:G,[1]raw_data!$A:$A,$B34) -> 1902.4655 | L34: =SUMIFS([1]raw_data!H:H,[1]raw_data!$A:$A,$B34) -> 2.35313 | M34: =SUMIFS([1]raw_data!I:I,[1]raw_data!$A:$A,$B34) -> 196.85104 | N34: =SUMIFS([1]raw_data!J:J,[1]raw_data!$A:$A,$B34) -> 0.92616372 | O34: =SUMIFS([1]raw_data!K:K,[1]raw_data!$A:$A,$B34) -> 105.18032 | P34: =SUMIFS([1]raw_data!L:L,[1]raw_data!$A:$A,$B34) -> 0.24 | Q34: =SUMIFS([1]raw_data!M:M,[1]raw_data!$A:$A,$B34) -> 51.547413 | R34: =SUMIFS([1]raw_data!N:N,[1]raw_data!$A:$A,$B34) -> 0.2 | S34: =SUMIFS([1]raw_data!O:O,[1]raw_data!$A:$A,$B34) -> 1581.6805 | T34: =SUMIFS([1]raw_data!P:P,[1]raw_data!$A:$A,$B34) -> 1.9424084 | U34: =SUMIFS([1]raw_data!Q:Q,[1]raw_data!$A:$A,$B34) -> 262.40267 | V34: =SUMIFS([1]raw_data!R:R,[1]raw_data!$A:$A,$B34) -> 1.5951134 | W34: =SUMIFS([1]raw_data!S:S,[1]raw_data!$A:$A,$B34) -> 540.64734 | X34: =SUMIFS([1]raw_data!T:T,[1]raw_data!$A:$A,$B34) -> 2.222973 | Y34: =SUMIFS([1]raw_data!U:U,[1]raw_data!$A:$A,$B34) -> 497.15257 | Z34: =SUMIFS([1]raw_data!V:V,[1]raw_data!$A:$A,$B34) -> 1.7905405 | AA34: =(I34+M34+Q34+U34+Y34)/5 -> 225.25266
B35: 049203 | C35: HASKELITE | D35: ANN STREET | E35: Grand Rapids | F35: =IFERROR(INDEX([1]raw_data!B:B,MATCH('SAIDI excl MEDs sort (5-yr avg)'!B13,[1]raw_data!A:A,0)),0) -> 189.11111 | G35: =SUMIFS([1]raw_data!C:C,[1]raw_data!$A:$A,$B35) -> 371.61435 | H35: =SUMIFS([1]raw_data!D:D,[1]raw_data!$A:$A,$B35) -> 2.5716487 | I35: =SUMIFS([1]raw_data!E:E,[1]raw_data!$A:$A,$B35) -> 371.51651 | J35: =SUMIFS([1]raw_data!F:F,[1]raw_data!$A:$A,$B35) -> 2.5701079 | K35: =SUMIFS([1]raw_data!G:G,[1]raw_data!$A:$A,$B35) -> 432.03947 | L35: =SUMIFS([1]raw_data!H:H,[1]raw_data!$A:$A,$B35) -> 6.3387358 | M35: =SUMIFS([1]raw_data!I:I,[1]raw_data!$A:$A,$B35) -> 432.03947 | N35: =SUMIFS([1]raw_data!J:J,[1]raw_data!$A:$A,$B35) -> 6.3387358 | O35: =SUMIFS([1]raw_data!K:K,[1]raw_data!$A:$A,$B35) -> 1454.5516 | P35: =SUMIFS([1]raw_data!L:L,[1]raw_data!$A:$A,$B35) -> 2.713355 | Q35: =SUMIFS([1]raw_data!M:M,[1]raw_data!$A:$A,$B35) -> 144.52451 | R35: =SUMIFS([1]raw_data!N:N,[1]raw_data!$A:$A,$B35) -> 1.4185668 | S35: =SUMIFS([1]raw_data!O:O,[1]raw_data!$A:$A,$B35) -> 771.49031 | T35: =SUMIFS([1]raw_data!P:P,[1]raw_data!$A:$A,$B35) -> 2.7517434 | U35: =SUMIFS([1]raw_data!Q:Q,[1]raw_data!$A:$A,$B35) -> 169.23026 | V35: =SUMIFS([1]raw_data!R:R,[1]raw_data!$A:$A,$B35) -> 1.6066946 | W35: =SUMIFS([1]raw_data!S:S,[1]raw_data!$A:$A,$B35) -> 526.32085 | X35: =SUMIFS([1]raw_data!T:T,[1]raw_data!$A:$A,$B35) -> 0.67125 | Y35: =SUMIFS([1]raw_data!U:U,[1]raw_data!$A:$A,$B35) -> 8.893812 | Z35: =SUMIFS([1]raw_data!V:V,[1]raw_data!$A:$A,$B35) -> 0.05375 | AA35: =(I35+M35+Q35+U35+Y35)/5 -> 225.24091
B36: 010003 | C36: WEALTHY STREET | D36: LOGAN | E36: Grand Rapids | F36: =IFERROR(INDEX([1]raw_data!B:B,MATCH('SAIDI excl MEDs sort (5-yr avg)'!B40,[1]raw_data!A:A,0)),0) -> 776.11111 | G36: =SUMIFS([1]raw_data!C:C,[1]raw_data!$A:$A,$B36) -> 178.91997 | H36: =SUMIFS([1]raw_data!D:D,[1]raw_data!$A:$A,$B36) -> 1.0380334 | I36: =SUMIFS([1]raw_data!E:E,[1]raw_data!$A:$A,$B36) -> 178.91997 | J36: =SUMIFS([1]raw_data!F:F,[1]raw_data!$A:$A,$B36) -> 1.0380334 | K36: =SUMIFS([1]raw_data!G:G,[1]raw_data!$A:$A,$B36) -> 638.49036 | L36: =SUMIFS([1]raw_data!H:H,[1]raw_data!$A:$A,$B36) -> 2.0253411 | M36: =SUMIFS([1]raw_data!I:I,[1]raw_data!$A:$A,$B36) -> 636.81327 | N36: =SUMIFS([1]raw_data!J:J,[1]raw_data!$A:$A,$B36) -> 2.0233918 | O36: =SUMIFS([1]raw_data!K:K,[1]raw_data!$A:$A,$B36) -> 154.49297 | P36: =SUMIFS([1]raw_data!L:L,[1]raw_data!$A:$A,$B36) -> 1.0253165 | Q36: =SUMIFS([1]raw_data!M:M,[1]raw_data!$A:$A,$B36) -> 154.49297 | R36: =SUMIFS([1]raw_data!N:N,[1]raw_data!$A:$A,$B36) -> 1.0253165 | S36: =SUMIFS([1]raw_data!O:O,[1]raw_data!$A:$A,$B36) -> 141.5696 | T36: =SUMIFS([1]raw_data!P:P,[1]raw_data!$A:$A,$B36) -> 1.0048876 | U36: =SUMIFS([1]raw_data!Q:Q,[1]raw_data!$A:$A,$B36) -> 141.5696 | V36: =SUMIFS([1]raw_data!R:R,[1]raw_data!$A:$A,$B36) -> 1.0048876 | W36: =SUMIFS([1]raw_data!S:S,[1]raw_data!$A:$A,$B36) -> 3.5635 | X36: =SUMIFS([1]raw_data!T:T,[1]raw_data!$A:$A,$B36) -> 0.028815368 | Y36: =SUMIFS([1]raw_data!U:U,[1]raw_data!$A:$A,$B36) -> 3.5635 | Z36: =SUMIFS([1]raw_data!V:V,[1]raw_data!$A:$A,$B36) -> 0.028815368 | AA36: =(I36+M36+Q36+U36+Y36)/5 -> 223.07186
B37: 028902 | C37: MILLER ROAD | D37: YALE STREET | E37: Flint | F37: =IFERROR(INDEX([1]raw_data!B:B,MATCH('SAIDI excl MEDs sort (5-yr avg)'!B6,[1]raw_data!A:A,0)),0) -> 320.2 | G37: =SUMIFS([1]raw_data!C:C,[1]raw_data!$A:$A,$B37) -> 809.63929 | H37: =SUMIFS([1]raw_data!D:D,[1]raw_data!$A:$A,$B37) -> 1.1122642 | I37: =SUMIFS([1]raw_data!E:E,[1]raw_data!$A:$A,$B37) -> 767.6696 | J37: =SUMIFS([1]raw_data!F:F,[1]raw_data!$A:$A,$B37) -> 1.0924528 | K37: =SUMIFS([1]raw_data!G:G,[1]raw_data!$A:$A,$B37) -> 73.691917 | L37: =SUMIFS([1]raw_data!H:H,[1]raw_data!$A:$A,$B37) -> 0.15813528 | M37: =SUMIFS([1]raw_data!I:I,[1]raw_data!$A:$A,$B37) -> 42.336726 | N37: =SUMIFS([1]raw_data!J:J,[1]raw_data!$A:$A,$B37) -> 0.12248629 | O37: =SUMIFS([1]raw_data!K:K,[1]raw_data!$A:$A,$B37) -> 71.744871 | P37: =SUMIFS([1]raw_data!L:L,[1]raw_data!$A:$A,$B37) -> 0.27014652 | Q37: =SUMIFS([1]raw_data!M:M,[1]raw_data!$A:$A,$B37) -> 43.205204 | R37: =SUMIFS([1]raw_data!N:N,[1]raw_data!$A:$A,$B37) -> 0.19047619 | S37: =SUMIFS([1]raw_data!O:O,[1]raw_data!$A:$A,$B37) -> 83.923342 | T37: =SUMIFS([1]raw_data!P:P,[1]raw_data!$A:$A,$B37) -> 0.40810556 | U37: =SUMIFS([1]raw_data!Q:Q,[1]raw_data!$A:$A,$B37) -> 83.923342 | V37: =SUMIFS([1]raw_data!R:R,[1]raw_data!$A:$A,$B37) -> 0.40810556 | W37: =SUMIFS([1]raw_data!S:S,[1]raw_data!$A:$A,$B37) -> 108.71189 | X37: =SUMIFS([1]raw_data!T:T,[1]raw_data!$A:$A,$B37) -> 0.3747698 | Y37: =SUMIFS([1]raw_data!U:U,[1]raw_data!$A:$A,$B37) -> 107.61728 | Z37: =SUMIFS([1]raw_data!V:V,[1]raw_data!$A:$A,$B37) -> 0.37384899 | AA37: =(I37+M37+Q37+U37+Y37)/5 -> 208.95043
B38: 003901 | C38: MAUMEE | D38: MAPLE ST | E38: Adrian | F38: =IFERROR(INDEX([1]raw_data!B:B,MATCH('SAIDI excl MEDs sort (5-yr avg)'!B43,[1]raw_data!A:A,0)),0) -> 1018.1429 | G38: =SUMIFS([1]raw_data!C:C,[1]raw_data!$A:$A,$B38) -> 2342.7304 | H38: =SUMIFS([1]raw_data!D:D,[1]raw_data!$A:$A,$B38) -> 2.1749137 | I38: =SUMIFS([1]raw_data!E:E,[1]raw_data!$A:$A,$B38) -> 160.19562 | J38: =SUMIFS([1]raw_data!F:F,[1]raw_data!$A:$A,$B38) -> 1.1864212 | K38: =SUMIFS([1]raw_data!G:G,[1]raw_data!$A:$A,$B38) -> 144.38391 | L38: =SUMIFS([1]raw_data!H:H,[1]raw_data!$A:$A,$B38) -> 0.64343318 | M38: =SUMIFS([1]raw_data!I:I,[1]raw_data!$A:$A,$B38) -> 75.302671 | N38: =SUMIFS([1]raw_data!J:J,[1]raw_data!$A:$A,$B38) -> 0.62384793 | O38: =SUMIFS([1]raw_data!K:K,[1]raw_data!$A:$A,$B38) -> 2143.7532 | P38: =SUMIFS([1]raw_data!L:L,[1]raw_data!$A:$A,$B38) -> 1.2723112 | Q38: =SUMIFS([1]raw_data!M:M,[1]raw_data!$A:$A,$B38) -> 78.417467 | R38: =SUMIFS([1]raw_data!N:N,[1]raw_data!$A:$A,$B38) -> 0.33237986 | S38: =SUMIFS([1]raw_data!O:O,[1]raw_data!$A:$A,$B38) -> 439.32337 | T38: =SUMIFS([1]raw_data!P:P,[1]raw_data!$A:$A,$B38) -> 3.1780186 | U38: =SUMIFS([1]raw_data!Q:Q,[1]raw_data!$A:$A,$B38) -> 425.32118 | V38: =SUMIFS([1]raw_data!R:R,[1]raw_data!$A:$A,$B38) -> 3.1341589 | W38: =SUMIFS([1]raw_data!S:S,[1]raw_data!$A:$A,$B38) -> 311.86291 | X38: =SUMIFS([1]raw_data!T:T,[1]raw_data!$A:$A,$B38) -> 1.3655674 | Y38: =SUMIFS([1]raw_data!U:U,[1]raw_data!$A:$A,$B38) -> 302.95351 | Z38: =SUMIFS([1]raw_data!V:V,[1]raw_data!$A:$A,$B38) -> 1.3482392 | AA38: =(I38+M38+Q38+U38+Y38)/5 -> 208.43809
B39: 090301 | C39: LEE STREET | D39: BLACK HILLS | E39: Grand Rapids | F39: =IFERROR(INDEX([1]raw_data!B:B,MATCH('SAIDI excl MEDs sort (5-yr avg)'!B26,[1]raw_data!A:A,0)),0) -> 1511.8 | G39: =SUMIFS([1]raw_data!C:C,[1]raw_data!$A:$A,$B39) -> 248.72991 | H39: =SUMIFS([1]raw_data!D:D,[1]raw_data!$A:$A,$B39) -> 1.6716418 | I39: =SUMIFS([1]raw_data!E:E,[1]raw_data!$A:$A,$B39) -> 248.72991 | J39: =SUMIFS([1]raw_data!F:F,[1]raw_data!$A:$A,$B39) -> 1.6716418 | K39: =SUMIFS([1]raw_data!G:G,[1]raw_data!$A:$A,$B39) -> 749.26773 | L39: =SUMIFS([1]raw_data!H:H,[1]raw_data!$A:$A,$B39) -> 1.056338 | M39: =SUMIFS([1]raw_data!I:I,[1]raw_data!$A:$A,$B39) -> 749.26773 | N39: =SUMIFS([1]raw_data!J:J,[1]raw_data!$A:$A,$B39) -> 1.056338 | O39: =SUMIFS([1]raw_data!K:K,[1]raw_data!$A:$A,$B39) -> 9.731454 | P39: =SUMIFS([1]raw_data!L:L,[1]raw_data!$A:$A,$B39) -> 0.056338028 | Q39: =SUMIFS([1]raw_data!M:M,[1]raw_data!$A:$A,$B39) -> 8.884976 | R39: =SUMIFS([1]raw_data!N:N,[1]raw_data!$A:$A,$B39) -> 0.042253521 | S39: =SUMIFS([1]raw_data!O:O,[1]raw_data!$A:$A,$B39) -> 1.880751 | T39: =SUMIFS([1]raw_data!P:P,[1]raw_data!$A:$A,$B39) -> 0.028169014 | U39: =SUMIFS([1]raw_data!Q:Q,[1]raw_data!$A:$A,$B39) -> 1.880751 | V39: =SUMIFS([1]raw_data!R:R,[1]raw_data!$A:$A,$B39) -> 0.028169014 | W39: =SUMIFS([1]raw_data!S:S,[1]raw_data!$A:$A,$B39) -> 8.320048 | X39: =SUMIFS([1]raw_data!T:T,[1]raw_data!$A:$A,$B39) -> 0.043478261 | Y39: =SUMIFS([1]raw_data!U:U,[1]raw_data!$A:$A,$B39) -> 8.320048 | Z39: =SUMIFS([1]raw_data!V:V,[1]raw_data!$A:$A,$B39) -> 0.043478261 | AA39: =(I39+M39+Q39+U39+Y39)/5 -> 203.41668
